Workbook
Name OLE_LINK1: Carátula!$A$1

Sheet Carátula

Sheet Indice
B1: Índice Boletin Anual de Empresas por Provincias (a 2 dígitos)
B3: Partidos de GBA | C3: Formosa | D3: Salta
CE4: 4° Trim 2015 | CF4: 1° Trim 2016
B5: Capital Federal | C5: Jujuy | D5: San Juan
B7: Resto de Bueno Aires | C7: La Pampa | D7: San Luis
B9: Catamarca | C9: La Rioja | D9: Santa Cruz
B11: Córdoba | C11: Mendoza | D11: Santa Fe
B13: Corrientes | C13: Misiones | D13: Santiago del Estero
B15: Chaco | C15: Neuquén | D15: Tucumán
B17: Chubut | C17: Río Negro | D17: Tierra del Fuego
B19: Entre Ríos

Sheet Metodología
A1: Nota metodológica
A4: ESTADÍSTICAS SOBRE EMPRESAS Y EMPLEO ASALARIADO REGISTRADO PORPROVINCIA
A6: El Boletín Provincial recopila una serie de tablas estadísticas elaboradas por el Observatorio de Empleo y Dinámica Empresarial[1] del Ministerio de Trabajo, Empleo y Seguridad Social.
A8: Tiene como fuente los registros administrativos del Sistema Integrado Previsional Argentino (SIPA) que contienen las declaraciones mensuales que realizan las empresas sobre el personal que tienen en relación de dependencia para el pago de los aportes y contribuciones patronales. La unidad de análisis es la empresa, definida como una unidad legal independiente[2] y está identificada por su Código Único de Identificación Tributaria (CUIT). Los indicadores se refieren al empleo asalariado registrado y a las empresas privadas de industria, comercio y servicios radicadas en todo el país.
A10: Las empresas se encuentran clasificadas según las provincias donde declaran sus ocupados. Es decir, las empresas que informan sobre sus trabajadores en diferentes provincias se contabilizan en cada una de las provincias donde declararon ocupados, por ello, la suma de las empresas desagregadas por provincia supera al total de empresas que operan efectivamente en el país. Asimismo, el empleo se encuentra clasificado por provincia de acuerdo a las zonas donde las empresas declaran que trabajan sus empleados.
A12: CONSTRUCCIÓN DE LA BASE LONGITUDINAL
A14: El grado de desagregación alcanzado y la frecuencia con que se actualiza la información permiten el tratamiento de series longitudinales que registran la evolución del empleo al nivel de cada empresa. Esto posibilita calcular por un lado el empleo creado por las empresas que expanden sus dotaciones de personal y el creado por empresas nuevas; y por otro lado, el empleo destruido por las empresas que contraen sus dotaciones y el destruido por las empresas que cierran[3].
A16: La construcción de esta base longitudinal involucra varios procesos cuyo objetivo final es el de consolidar, a partir del registro administrativo, un sistema de información estadístico. Una de las principales dificultades estadísticas que presenta el registro, y que se deben resolver es la discontinuidad de la información.
A18: Es frecuente encontrar en un registro administrativo vacíos de información producidos por distintas causas (declaraciones tardías, errores de carga, etc.) y que no reflejan cambios reales en la información. Podría citarse como ejemplo el caso de empresas que aparecen en el registro con meses de falta de declaración seguidos y antecedidos por meses de declaración positiva de empleo. En estos casos, los valores nulos se completan utilizando la información de los períodos anterior y posterior. Sin embargo, cuando el período sin declaraciones de una firma es prolongado, se respetan los datos consignados porque se entiende que reflejan discontinuidades reales en el empleo[4]
A20: TOTAL DE FIRMAS Y FIRMAS LOCALES
A22: Se considera que son “firmas locales” a aquellas firmas que declaran una mayor proporción de su empleo en la provincia de referencia. Es decir, una misma firma diversificada en el territorio nacional será “firma local” en la provincia donde declara más empleo y “firma no local” en el resto de las provincias donde declare la otra parte del empleo.
A24: Esta distinción es particularmente importante para analizar demografía de empresas. La entrada y salida de las firmas no locales es muy volátil, mientras que la movilidad de las firmas locales suele ser más estable reflejando de mejor manera los procesos de expansión del tejido productivo en las regiones.
... A30: Quedan excluidos del registro:
A31: O | B31: Trabajadores del sector público.
A32: O | B32: Trabajadores en casas particulares.
A33: O | B33: Asalariados no registrados.
A34: O | B34: Trabajadores por cuenta propia, patrones y trabajo familiar.
A38: DEFINICIONES
A40: A continuación se presentan las definiciones que se utilizaron para el análisis de la demografía (movilidad) de las empresas:
A42: Empresas que abren: Son empresas que inician actividades durante el período de referencia. Se identifica el inicio de actividades de una firma, a partir de la fecha de las primeras declaraciones de personal ocupado de las nuevas firmas. Para el análisis de la antigüedad de las firmas se toma en cuenta también la fecha de ingreso al padrón de empleadores de AFIP.
A44: Empresas que cierran: Se definen a partir de un criterio empírico que considera como cerrada (dada de baja) a toda empresa que no declara personal ocupado a lo largo de un año (4 trimestres) [5]. Para poder medir el impacto de los cierres en los flujos de empleo, se considera que el momento en que se produce el cierre de la empresa es el primer período de empleo nulo[6]
A46: Cambio neto de empresas: Es la diferencia entre las aperturas y los cierres de empresas.
A48: Tasas de entrada y tasa de salida de empresas: Es la cantidad de empresas creadas/destruidas en el período dividido por el total de empresas existentes a lo largo del período. Es decir, en el denominador se incluyen a las empresas activas (aperturas, sobrevivientes de periodos anteriores) así como a los cierres del periodo.
A50: Tasa de cambio neto: Es la diferencia entre la tasa de entrada y de salida de empresas.
A54: RAMA DE ACTIVIDAD ECONOMICA
A56: Es la rama de actividad principal, codificada con la revisión 3 del código CIIU. La información original de rama surge del padrón de contribuyentes de AFIP y se mejora incorporando información de otras fuentes: principalmente la Encuesta de Indicadores Laborales (EIL), guías de empresas, consultas a Cámaras y Organismos Reguladores, y otras bases de registros de empresas.
A58: ESTRATIFICACION DE LAS EMPRESAS POR TAMAÑO
A60: La estratificación por tamaño para una empresa en determinado trimestre se realiza a partir del empleo promedio declarado por la firma durante los últimos cuatro trimestres. Por ejemplo: para calcular el tamaño de una empresa en el 4to trimestre del año 2015, se toma en cuenta el promedio del empleo declarardo por la misma en cada trimestre del año 2015.
A62: Los rangos de empleo utilizados en cada estrato de tamaño varían según rama de actividad, atendiendo a diferencias sectoriales en la productividad media del trabajo y a las pautas establecidas por el país para la aplicación de políticas orientadas a la pequeña y mediana empresa. Estos tramos se determinaron a partir del nivel de ventas de las empresas definido por la SEPyME en la Resolución 24/2001 que establece el nivel máximo de ventas para cada categoría de empresa (micro, pequeña, mediana y gran empresa) según el sector en el que desarrollan su actividad.
... A67: CORTES POR TAMAÑO ($)
B68: Agropecuario | C68: Industria y Minería | D68: Comercio | E68: Servicios
A69: Micro | B69: 150000 | C69: 500000 | D69: 1000000 | E69: 250000
A70: Pequeña | B70: 1000000 | C70: 3000000 | D70: 6000000 | E70: 1800000
A71: Mediana | B71: 6000000 | C71: 24000000 | D71: 48000000 | E71: 12000000
A72: Fuente: Resolución SEPyME N° 24/01
A74: A partir de las estimaciones realizadas se definieron tramos ocupacionales, que ponen en evidencia las fuertes diferencias entre los distintos sectores (industria, comercio y servicios) y entre las distintas ramas de actividad al interior de cada sector. Se presentan a continuación los resultados que surgieron de las estimaciones realizadas para definir los tramos de empleo que permiten clasificar a las firmas según su tamaño económico.
A76: Se enuncian los topes máximos para cada categoría, con una desagregación de dos dígitos de la CIIU Revisión 3.
A78: TOPES MÁXIMOS PARA CADA CATEGORÍA: INDUSTRIA MANUFACTURERA
A79: Rama de actividad | C79: Micro | D79: Pequeña | E79: Mediana
A80: 15 | B80: Elaboración de productos alimenticios y bebidas | C80: 6 | D80: 34 | E80: 128
...

Sheet Partidos de GBA
D1: Volver al índice
A2: PARTIDOS DE GBA
A3: Empresas del sector privado por rama de actividad - Activas en cada año
B4: Ramas de actividad | C4: 1996 | D4: 1997 | E4: 1998 | F4: 1999 | G4: 2000 | H4: 2001 | I4: 2002 | J4: 2003 | K4: 2004 | L4: 2005 | M4: 2006 | N4: 2007 | O4: 2008 | P4: 2009 | Q4: 2010 | R4: 2011 | S4: 2012 | T4: 2013 | U4: 2014 | V4: 2015 | W4: 2016 | X4: 2017 | Y4: 2018 | Z4: 2019 | AA4: 2020 | AB4: 2021 | AC4: 2022 | AD4: 2023 | AE4: 2024
D5: 2º Trim 1996 | F5: 3º Trim 1996 | H5: 4º Trim 1996 | J5: 1º Trim 1997 | L5: 2º Trim 1997 | N5: 3º Trim 1997 | P5: 4º Trim 1997 | R5: 1º Trim 1998
A6: A | B6: AGRICULTURA, GANADERIA, CAZA Y SILVICULTURA | C6: 1271 | D6: 1270 | E6: 1264 | F6: 1328 | G6: 1006 | H6: 1009 | I6: 993 | J6: 1108 | K6: 1261 | L6: 1344 | M6: 1436 | N6: 1538 | O6: 1511 | P6: 1487 | Q6: 1468 | R6: 1478 | S6: 1434 | T6: 1381 | U6: 1355 | V6: 1377 | W6: 1394 | X6: 1412 | Y6: 1432 | Z6: 1447 | AA6: 1470 | AB6: 1546 | AC6: 2156 | AD6: 2318 | AE6: 2285
A7: 1 | B7: Agricultura y ganaderia | C7: 1238 | D7: 1232 | E7: 1230 | F7: 1290 | G7: 971 | H7: 976 | I7: 963 | J7: 1076 | K7: 1226 | L7: 1305 | M7: 1399 | N7: 1496 | O7: 1470 | P7: 1440 | Q7: 1421 | R7: 1434 | S7: 1391 | T7: 1335 | U7: 1310 | V7: 1332 | W7: 1351 | X7: 1370 | Y7: 1389 | Z7: 1408 | AA7: 1431 | AB7: 1502 | AC7: 2106 | AD7: 2256 | AE7: 2227
A8: 2 | B8: Silvicultura, extracción de madera | C8: 33 | D8: 38 | E8: 34 | F8: 38 | G8: 35 | H8: 33 | I8: 30 | J8: 32 | K8: 35 | L8: 39 | M8: 37 | N8: 42 | O8: 41 | P8: 47 | Q8: 47 | R8: 44 | S8: 43 | T8: 46 | U8: 45 | V8: 45 | W8: 43 | X8: 42 | Y8: 43 | Z8: 39 | AA8: 39 | AB8: 44 | AC8: 50 | AD8: 62 | AE8: 58
A9: B | B9: PESCA Y SERVICIOS CONEXOS | C9: 4 | D9: 6 | E9: 8 | F9: 11 | G9: s.d. | H9: s.d. | I9: 5 | J9: s.d. | K9: 7 | L9: 9 | M9: 11 | N9: 11 | O9: 9 | P9: 9 | Q9: 7 | R9: 8 | S9: 9 | T9: 14 | U9: 10 | V9: 11 | W9: 11 | X9: 9 | Y9: 10 | Z9: 13 | AA9: 12 | AB9: 15 | AC9: 8 | AD9: 18 | AE9: 21
A10: 5 | B10: Pesca y actividades relacionadas con la pesca | C10: 4 | D10: 6 | E10: 8 | F10: 11 | G10: s.d. | H10: s.d. | I10: 5 | J10: s.d. | K10: 7 | L10: 9 | M10: 11 | N10: 11 | O10: 9 | P10: 9 | Q10: 7 | R10: 8 | S10: 9 | T10: 14 | U10: 10 | V10: 11 | W10: 11 | X10: 9 | Y10: 10 | Z10: 13 | AA10: 12 | AB10: 15 | AC10: 8 | AD10: 18 | AE10: 21
A11: C | B11: EXPLOTACION DE MINAS Y CANTERAS | C11: 52 | D11: 53 | E11: 56 | F11: 58 | G11: 56 | H11: 53 | I11: 46 | J11: 51 | K11: 54 | L11: 58 | M11: 64 | N11: 74 | O11: 70 | P11: 71 | Q11: 72 | R11: 66 | S11: 63 | T11: 74 | U11: 71 | V11: 69 | W11: 65 | X11: 61 | Y11: 65 | Z11: 67 | AA11: 70 | AB11: 72 | AC11: 92 | AD11: 94 | AE11: 92
A12: 11 | B12: Extraccion de petroleo crudo y gas natural | C12: 19 | D12: 17 | E12: 18 | F12: 18 | G12: 19 | H12: 16 | I12: 14 | J12: 18 | K12: s.d. | L12: s.d. | M12: s.d. | N12: 21 | O12: 23 | P12: s.d. | Q12: s.d. | R12: s.d. | S12: s.d. | T12: s.d. | U12: s.d. | V12: s.d. | W12: s.d. | X12: s.d. | Y12: 23 | Z12: 26 | AA12: 28 | AB12: 28 | AC12: 33 | AD12: 33 | AE12: 36
A13: 13 | B13: Extraccion de minerales metaliferos | C13: 4 | D13: 4 | E13: s.d. | F13: s.d. | G13: s.d. | H13: s.d. | I13: s.d. | J13: s.d. | K13: s.d. | L13: s.d. | M13: s.d. | N13: 4 | O13: s.d. | P13: s.d. | Q13: s.d. | R13: s.d. | S13: s.d. | T13: s.d. | U13: s.d. | V13: s.d. | W13: s.d. | X13: s.d. | Y13: s.d. | Z13: s.d. | AA13: s.d. | AB13: s.d. | AC13: 4 | AD13: 4 | AE13: s.d.
A14: 14 | B14: Explotacion de otras minas y canteras | C14: 29 | D14: 32 | E14: s.d. | F14: s.d. | G14: s.d. | H14: s.d. | I14: s.d. | J14: s.d. | K14: 37 | L14: 39 | M14: 42 | N14: 49 | O14: s.d. | P14: 44 | Q14: 48 | R14: 44 | S14: 40 | T14: 44 | U14: 44 | V14: 43 | W14: 41 | X14: 37 | Y14: s.d. | Z14: s.d. | AA14: s.d. | AB14: s.d. | AC14: 55 | AD14: 57 | AE14: s.d.
A15: D | B15: INDUSTRIA MANUFACTURERA | C15: 15570 | D15: 15445 | E15: 15019 | F15: 15544 | G15: 14185 | H15: 13219 | I15: 12399 | J15: 13334 | K15: 14894 | L15: 15955 | M15: 16910 | N15: 17669 | O15: 17992 | P15: 17919 | Q15: 18014 | R15: 18186 | S15: 18233 | T15: 18198 | U15: 18113 | V15: 18239 | W15: 18061 | X15: 17791 | Y15: 17219 | Z15: 16632 | AA15: 16313 | AB15: 16483 | AC15: 17402 | AD15: 17490 | AE15: 17226
A16: 15 | B16: Alimentos | C16: 2270 | D16: 2220 | E16: 2077 | F16: 2104 | G16: 1873 | H16: 1787 | I16: 1692 | J16: 1797 | K16: 2065 | L16: 2127 | M16: 2230 | N16: 2301 | O16: 2372 | P16: 2403 | Q16: 2406 | R16: 2453 | S16: 2489 | T16: 2514 | U16: 2522 | V16: 2534 | W16: 2539 | X16: 2561 | Y16: 2536 | Z16: 2517 | AA16: 2468 | AB16: 2536 | AC16: 2817 | AD16: 2915 | AE16: 2922
A17: 16 | B17: Tabaco | C17: s.d. | D17: s.d. | E17: s.d. | F17: s.d. | G17: s.d. | H17: s.d. | I17: 6 | J17: 6 | K17: 7 | L17: 6 | M17: 5 | N17: 5 | O17: 4 | P17: 5 | Q17: 5 | R17: 5 | S17: 5 | T17: 4 | U17: 4 | V17: 4 | W17: 4 | X17: 5 | Y17: 5 | Z17: 6 | AA17: 6 | AB17: 7 | AC17: 7 | AD17: 7 | AE17: 7
A18: 17 | B18: Productos textiles | C18: 954 | D18: 948 | E18: 929 | F18: 953 | G18: 818 | H18: 795 | I18: 724 | J18: 791 | K18: 876 | L18: 947 | M18: 1008 | N18: 1080 | O18: 1078 | P18: 1060 | Q18: 1079 | R18: 1088 | S18: 1102 | T18: 1110 | U18: 1111 | V18: 1111 | W18: 1118 | X18: 1096 | Y18: 1045 | Z18: 1004 | AA18: 991 | AB18: 1002 | AC18: 1071 | AD18: 1075 | AE18: 1072
A19: 18 | B19: Confecciones | C19: 642 | D19: 600 | E19: 615 | F19: 608 | G19: 536 | H19: 457 | I19: 395 | J19: 443 | K19: 547 | L19: 609 | M19: 710 | N19: 759 | O19: 782 | P19: 775 | Q19: 785 | R19: 806 | S19: 780 | T19: 778 | U19: 803 | V19: 816 | W19: 795 | X19: 759 | Y19: 716 | Z19: 649 | AA19: 602 | AB19: 581 | AC19: 709 | AD19: 723 | AE19: 728
A20: 19 | B20: Calzado y cuero | C20: 703 | D20: 671 | E20: 616 | F20: 626 | G20: 567 | H20: 504 | I20: 472 | J20: 552 | K20: 654 | L20: 717 | M20: 779 | N20: 840 | O20: 852 | P20: 858 | Q20: 884 | R20: 919 | S20: 942 | T20: 955 | U20: 940 | V20: 960 | W20: 949 | X20: 909 | Y20: 835 | Z20: 732 | AA20: 700 | AB20: 678 | AC20: 697 | AD20: 690 | AE20: 649
A21: 20 | B21: Madera | C21: 641 | D21: 625 | E21: 596 | F21: 613 | G21: 568 | H21: 506 | I21: 448 | J21: 474 | K21: 545 | L21: 588 | M21: 630 | N21: 654 | O21: 666 | P21: 642 | Q21: 628 | R21: 625 | S21: 612 | T21: 596 | U21: 590 | V21: 567 | W21: 536 | X21: 512 | Y21: 494 | Z21: 471 | AA21: 463 | AB21: 477 | AC21: 492 | AD21: 505 | AE21: 482
A22: 21 | B22: Papel | C22: 340 | D22: 346 | E22: 338 | F22: 359 | G22: 328 | H22: 306 | I22: 305 | J22: 338 | K22: 363 | L22: 383 | M22: 406 | N22: 416 | O22: 431 | P22: 434 | Q22: 437 | R22: 439 | S22: 440 | T22: 439 | U22: 435 | V22: 445 | W22: 453 | X22: 443 | Y22: 431 | Z22: 416 | AA22: 405 | AB22: 414 | AC22: 428 | AD22: 430 | AE22: 419
A23: 22 | B23: Edición e impresión | C23: 633 | D23: 645 | E23: 688 | F23: 724 | G23: 670 | H23: 637 | I23: 597 | J23: 622 | K23: 694 | L23: 767 | M23: 822 | N23: 862 | O23: 883 | P23: 906 | Q23: 905 | R23: 886 | S23: 860 | T23: 862 | U23: 852 | V23: 842 | W23: 838 | X23: 798 | Y23: 756 | Z23: 732 | AA23: 695 | AB23: 681 | AC23: 721 | AD23: 719 | AE23: 686
A24: 23 | B24: Productos de petróleo | C24: 48 | D24: 43 | E24: 41 | F24: 43 | G24: 36 | H24: 34 | I24: 28 | J24: 31 | K24: 33 | L24: 34 | M24: 31 | N24: 31 | O24: 30 | P24: 30 | Q24: 31 | R24: 32 | S24: 32 | T24: 33 | U24: 34 | V24: 35 | W24: 34 | X24: 31 | Y24: 31 | Z24: 30 | AA24: 29 | AB24: 30 | AC24: 31 | AD24: 32 | AE24: 32
A25: 24 | B25: Productos químicos | C25: 912 | D25: 919 | E25: 912 | F25: 987 | G25: 913 | H25: 898 | I25: 886 | J25: 942 | K25: 1001 | L25: 1044 | M25: 1060 | N25: 1049 | O25: 1046 | P25: 1045 | Q25: 1046 | R25: 1042 | S25: 1050 | T25: 1049 | U25: 1054 | V25: 1067 | W25: 1045 | X25: 1054 | Y25: 1041 | Z25: 1052 | AA25: 1058 | AB25: 1073 | AC25: 1138 | AD25: 1150 | AE25: 1134
A26: 25 | B26: Productos de caucho y plástico | C26: 1312 | D26: 1307 | E26: 1303 | F26: 1401 | G26: 1337 | H26: 1254 | I26: 1195 | J26: 1270 | K26: 1348 | L26: 1433 | M26: 1494 | N26: 1525 | O26: 1552 | P26: 1558 | Q26: 1543 | R26: 1568 | S26: 1575 | T26: 1581 | U26: 1577 | V26: 1622 | W26: 1618 | X26: 1602 | Y26: 1560 | Z26: 1532 | AA26: 1532 | AB26: 1559 | AC26: 1585 | AD26: 1580 | AE26: 1555
A27: 26 | B27: Otros minerales no metálicos | C27: 491 | D27: 460 | E27: 437 | F27: 456 | G27: 422 | H27: 378 | I27: 357 | J27: 367 | K27: 399 | L27: 416 | M27: 431 | N27: 466 | O27: 460 | P27: 454 | Q27: 454 | R27: 460 | S27: 461 | T27: 459 | U27: 447 | V27: 454 | W27: 450 | X27: 441 | Y27: 439 | Z27: 427 | AA27: 424 | AB27: 438 | AC27: 466 | AD27: 468 | AE27: 461
A28: 27 | B28: Metales comunes | C28: 475 | D28: 477 | E28: 438 | F28: 459 | G28: 434 | H28: 397 | I28: 379 | J28: 399 | K28: 447 | L28: 483 | M28: 496 | N28: 513 | O28: 524 | P28: 510 | Q28: 513 | R28: 528 | S28: 523 | T28: 511 | U28: 511 | V28: 503 | W28: 483 | X28: 468 | Y28: 448 | Z28: 442 | AA28: 442 | AB28: 454 | AC28: 452 | AD28: 439 | AE28: 431
A29: 28 | B29: Otros productos de metal | C29: 2628 | D29: 2651 | E29: 2589 | F29: 2705 | G29: 2464 | H29: 2299 | I29: 2148 | J29: 2319 | K29: 2599 | L29: 2804 | M29: 2995 | N29: 3154 | O29: 3228 | P29: 3203 | Q29: 3206 | R29: 3229 | S29: 3251 | T29: 3262 | U29: 3220 | V29: 3252 | W29: 3223 | X29: 3188 | Y29: 3088 | Z29: 2961 | AA29: 2896 | AB29: 2903 | AC29: 2991 | AD29: 2966 | AE29: 2898
A30: 29 | B30: Maquinaria y equipo | C30: 932 | D30: 952 | E30: 951 | F30: 998 | G30: 933 | H30: 856 | I30: 799 | J30: 881 | K30: 965 | L30: 1056 | M30: 1097 | N30: 1146 | O30: 1149 | P30: 1127 | Q30: 1137 | R30: 1136 | S30: 1147 | T30: 1125 | U30: 1113 | V30: 1115 | W30: 1081 | X30: 1061 | Y30: 1042 | Z30: 1028 | AA30: 1014 | AB30: 1003 | AC30: 1022 | AD30: 1017 | AE30: 1017
A31: 30 | B31: Maquinaria de oficina | C31: s.d. | D31: s.d. | E31: s.d. | F31: s.d. | G31: s.d. | H31: s.d. | I31: 11 | J31: 12 | K31: 14 | L31: 15 | M31: 20 | N31: 21 | O31: 20 | P31: 20 | Q31: 19 | R31: 20 | S31: 18 | T31: 19 | U31: 20 | V31: 25 | W31: 23 | X31: 20 | Y31: 21 | Z31: 16 | AA31: 18 | AB31: 23 | AC31: 30 | AD31: 32 | AE31: 29
A32: 31 | B32: Aparatos eléctricos | C32: 397 | D32: 401 | E32: 372 | F32: 389 | G32: 351 | H32: 324 | I32: 301 | J32: 324 | K32: 359 | L32: 379 | M32: 398 | N32: 419 | O32: 427 | P32: 441 | Q32: 453 | R32: 468 | S32: 480 | T32: 466 | U32: 473 | V32: 493 | W32: 484 | X32: 479 | Y32: 470 | Z32: 463 | AA32: 456 | AB32: 469 | AC32: 494 | AD32: 500 | AE32: 492
A33: 32 | B33: Radio y televisión | C33: 54 | D33: 53 | E33: 48 | F33: 48 | G33: 42 | H33: 37 | I33: 34 | J33: 36 | K33: 40 | L33: 42 | M33: 42 | N33: 46 | O33: 47 | P33: 48 | Q33: 49 | R33: 52 | S33: 58 | T33: 56 | U33: 58 | V33: 55 | W33: 54 | X33: 56 | Y33: 56 | Z33: 51 | AA33: 53 | AB33: 52 | AC33: 50 | AD33: 51 | AE33: 50
A34: 33 | B34: Instrumentos médicos | C34: 118 | D34: 125 | E34: 125 | F34: 137 | G34: 120 | H34: 115 | I34: 116 | J34: 134 | K34: 146 | L34: 152 | M34: 158 | N34: 165 | O34: 182 | P34: 180 | Q34: 191 | R34: 188 | S34: 182 | T34: 191 | U34: 184 | V34: 184 | W34: 187 | X34: 189 | Y34: 182 | Z34: 183 | AA34: 183 | AB34: 190 | AC34: 206 | AD34: 206 | AE34: 209
A35: 34 | B35: Automotores | C35: 574 | D35: 585 | E35: 556 | F35: 566 | G35: 534 | H35: 518 | I35: 497 | J35: 526 | K35: 575 | L35: 614 | M35: 634 | N35: 655 | O35: 655 | P35: 636 | Q35: 640 | R35: 638 | S35: 631 | T35: 610 | U35: 601 | V35: 600 | W35: 592 | X35: 583 | Y35: 554 | Z35: 518 | AA35: 514 | AB35: 524 | AC35: 522 | AD35: 514 | AE35: 507
A36: 35 | B36: Otros equipo de transporte | C36: 162 | D36: 156 | E36: 156 | F36: 151 | G36: 149 | H36: 131 | I36: 124 | J36: 131 | K36: 163 | L36: 177 | M36: 202 | N36: 224 | O36: 234 | P36: 228 | Q36: 229 | R36: 227 | S36: 221 | T36: 209 | U36: 194 | V36: 192 | W36: 195 | X36: 178 | Y36: 174 | Z36: 170 | AA36: 164 | AB36: 168 | AC36: 179 | AD36: 176 | AE36: 164
A37: 36 | B37: Muebles | C37: 1240 | D37: 1215 | E37: 1191 | F37: 1173 | G37: 1047 | H37: 943 | I37: 851 | J37: 900 | K37: 1015 | L37: 1115 | M37: 1207 | N37: 1263 | O37: 1286 | P37: 1278 | Q37: 1296 | R37: 1302 | S37: 1292 | T37: 1287 | U37: 1290 | V37: 1279 | W37: 1281 | X37: 1285 | Y37: 1223 | Z37: 1161 | AA37: 1129 | AB37: 1145 | AC37: 1208 | AD37: 1210 | AE37: 1200
A38: 37 | B38: Reciclamiento de desperdicios y desechos | C38: 26 | D38: 29 | E38: 27 | F38: 29 | G38: 31 | H38: 30 | I38: 34 | J38: 39 | K38: 39 | L38: 47 | M38: 55 | N38: 75 | O38: 84 | P38: 78 | Q38: 78 | R38: 75 | S38: 82 | T38: 82 | U38: 80 | V38: 84 | W38: 79 | X38: 73 | Y38: 72 | Z38: 71 | AA38: 71 | AB38: 76 | AC38: 86 | AD38: 85 | AE38: 82
A39: E | B39: ELECTRICIDAD, GAS Y AGUA | C39: 33 | D39: 27 | E39: 27 | F39: 34 | G39: 35 | H39: 34 | I39: 31 | J39: 30 | K39: 31 | L39: 34 | M39: 34 | N39: 35 | O39: 33 | P39: 33 | Q39: 35 | R39: 35 | S39: 40 | T39: 39 | U39: 36 | V39: 40 | W39: 38 | X39: 43 | Y39: 49 | Z39: 44 | AA39: 41 | AB39: 48 | AC39: 66 | AD39: 54 | AE39: 64
A40: 40 | B40: Electricidad, gas y agua | C40: 21 | D40: 14 | E40: 16 | F40: 21 | G40: 22 | H40: 20 | I40: 18 | J40: 18 | K40: 18 | L40: 20 | M40: 18 | N40: 20 | O40: 19 | P40: 20 | Q40: 23 | R40: 23 | S40: 28 | T40: 27 | U40: 24 | V40: 27 | W40: 25 | X40: 31 | Y40: 36 | Z40: 31 | AA40: 28 | AB40: 34 | AC40: 45 | AD40: 35 | AE40: 46
...

Sheet Capital Federal
D1: Volver al índice
A2: CAPITAL FEDERAL
A3: Empresas del sector privado por rama de actividad - Activas en cada año
B4: Ramas de actividad | C4: 1996 | D4: 1997 | E4: 1998 | F4: 1999 | G4: 2000 | H4: 2001 | I4: 2002 | J4: 2003 | K4: 2004 | L4: 2005 | M4: 2006 | N4: 2007 | O4: 2008 | P4: 2009 | Q4: 2010 | R4: 2011 | S4: 2012 | T4: 2013 | U4: 2014 | V4: 2015 | W4: 2016 | X4: 2017 | Y4: 2018 | Z4: 2019 | AA4: 2020 | AB4: 2021 | AC4: 2022 | AD4: 2023 | AE4: 2024
D5: 2º Trim 1996 | F5: 3º Trim 1996 | H5: 4º Trim 1996 | J5: 1º Trim 1997 | L5: 2º Trim 1997 | N5: 3º Trim 1997 | P5: 4º Trim 1997 | R5: 1º Trim 1998
A6: A | B6: AGRICULTURA, GANADERIA, CAZA Y SILVICULTURA | C6: 2417 | D6: 2401 | E6: 2239 | F6: 2175 | G6: 1443 | H6: 1443 | I6: 1445 | J6: 1510 | K6: 1687 | L6: 1799 | M6: 1909 | N6: 1984 | O6: 1967 | P6: 1913 | Q6: 1931 | R6: 1959 | S6: 1969 | T6: 1956 | U6: 1933 | V6: 1950 | W6: 1934 | X6: 1937 | Y6: 1923 | Z6: 1900 | AA6: 1896 | AB6: 1958 | AC6: 2410 | AD6: 2501 | AE6: 2487
A7: 1 | B7: Agricultura y ganaderia | C7: 2373 | D7: 2363 | E7: 2197 | F7: 2130 | G7: 1411 | H7: 1410 | I7: 1409 | J7: 1473 | K7: 1649 | L7: 1759 | M7: 1868 | N7: 1941 | O7: 1928 | P7: 1868 | Q7: 1888 | R7: 1921 | S7: 1932 | T7: 1919 | U7: 1893 | V7: 1908 | W7: 1888 | X7: 1894 | Y7: 1883 | Z7: 1862 | AA7: 1860 | AB7: 1920 | AC7: 2360 | AD7: 2454 | AE7: 2447
A8: 2 | B8: Silvicultura, extracción de madera | C8: 44 | D8: 38 | E8: 42 | F8: 45 | G8: 32 | H8: 33 | I8: 36 | J8: 37 | K8: 38 | L8: 40 | M8: 41 | N8: 43 | O8: 39 | P8: 45 | Q8: 43 | R8: 38 | S8: 37 | T8: 37 | U8: 40 | V8: 42 | W8: 46 | X8: 43 | Y8: 40 | Z8: 38 | AA8: 36 | AB8: 38 | AC8: 50 | AD8: 47 | AE8: 40
A9: B | B9: PESCA Y SERVICIOS CONEXOS | C9: 74 | D9: 78 | E9: 75 | F9: 61 | G9: 49 | H9: 50 | I9: 57 | J9: 61 | K9: 63 | L9: 59 | M9: 62 | N9: 61 | O9: 56 | P9: 54 | Q9: 52 | R9: 48 | S9: 45 | T9: 41 | U9: 38 | V9: 37 | W9: 41 | X9: 40 | Y9: 42 | Z9: 43 | AA9: 41 | AB9: 40 | AC9: 39 | AD9: 42 | AE9: 45
A10: 5 | B10: Pesca y actividades relacionadas con la pesca | C10: 74 | D10: 78 | E10: 75 | F10: 61 | G10: 49 | H10: 50 | I10: 57 | J10: 61 | K10: 63 | L10: 59 | M10: 62 | N10: 61 | O10: 56 | P10: 54 | Q10: 52 | R10: 48 | S10: 45 | T10: 41 | U10: 38 | V10: 37 | W10: 41 | X10: 40 | Y10: 42 | Z10: 43 | AA10: 41 | AB10: 40 | AC10: 39 | AD10: 42 | AE10: 45
A11: C | B11: EXPLOTACION DE MINAS Y CANTERAS | C11: 159 | D11: 175 | E11: 163 | F11: 163 | G11: 139 | H11: 136 | I11: 116 | J11: 125 | K11: 137 | L11: 144 | M11: 164 | N11: 176 | O11: 187 | P11: 194 | Q11: 199 | R11: 206 | S11: 210 | T11: 201 | U11: 196 | V11: 195 | W11: 199 | X11: 196 | Y11: 202 | Z11: 199 | AA11: 196 | AB11: 207 | AC11: 203 | AD11: 192 | AE11: 191
A12: 11 | B12: Extraccion de petroleo crudo y gas natural | C12: 88 | D12: 100 | E12: 85 | F12: 89 | G12: 88 | H12: 86 | I12: 72 | J12: 75 | K12: 78 | L12: 85 | M12: 97 | N12: 110 | O12: 121 | P12: 126 | Q12: 126 | R12: 131 | S12: 130 | T12: 123 | U12: 122 | V12: 122 | W12: 123 | X12: 118 | Y12: 123 | Z12: 118 | AA12: 117 | AB12: 118 | AC12: 107 | AD12: 103 | AE12: 103
A13: 13 | B13: Extraccion de minerales metaliferos | C13: 10 | D13: 10 | E13: 11 | F13: 10 | G13: 7 | H13: 7 | I13: 5 | J13: 5 | K13: 6 | L13: 7 | M13: 12 | N13: 14 | O13: 15 | P13: 16 | Q13: 17 | R13: 18 | S13: 19 | T13: 16 | U13: 14 | V13: 16 | W13: 14 | X13: 13 | Y13: 15 | Z13: 15 | AA13: 13 | AB13: 15 | AC13: 15 | AD13: 17 | AE13: 15
A14: 14 | B14: Explotacion de otras minas y canteras | C14: 61 | D14: 65 | E14: 67 | F14: 64 | G14: 44 | H14: 43 | I14: 39 | J14: 45 | K14: 53 | L14: 52 | M14: 55 | N14: 52 | O14: 51 | P14: 52 | Q14: 56 | R14: 57 | S14: 61 | T14: 62 | U14: 60 | V14: 57 | W14: 62 | X14: 65 | Y14: 64 | Z14: 66 | AA14: 66 | AB14: 74 | AC14: 81 | AD14: 72 | AE14: 73
A15: D | B15: INDUSTRIA MANUFACTURERA | C15: 13269 | D15: 13381 | E15: 13293 | F15: 13034 | G15: 10941 | H15: 10178 | I15: 9474 | J15: 10109 | K15: 11119 | L15: 11645 | M15: 12459 | N15: 12951 | O15: 13073 | P15: 12831 | Q15: 12749 | R15: 12720 | S15: 12501 | T15: 12416 | U15: 12287 | V15: 12319 | W15: 12013 | X15: 11750 | Y15: 11314 | Z15: 10856 | AA15: 10656 | AB15: 10648 | AC15: 11150 | AD15: 10995 | AE15: 10891
A16: 15 | B16: Alimentos | C16: 1992 | D16: 1992 | E16: 1956 | F16: 1811 | G16: 1536 | H16: 1435 | I16: 1383 | J16: 1427 | K16: 1605 | L16: 1622 | M16: 1654 | N16: 1719 | O16: 1728 | P16: 1719 | Q16: 1745 | R16: 1767 | S16: 1738 | T16: 1727 | U16: 1731 | V16: 1737 | W16: 1734 | X16: 1750 | Y16: 1742 | Z16: 1713 | AA16: 1747 | AB16: 1787 | AC16: 1970 | AD16: 1990 | AE16: 2053
A17: 16 | B17: Tabaco | C17: 6 | D17: 6 | E17: 7 | F17: 6 | G17: 6 | H17: 6 | I17: 7 | J17: 8 | K17: 9 | L17: 9 | M17: 7 | N17: 7 | O17: 6 | P17: 6 | Q17: 7 | R17: 10 | S17: 9 | T17: 8 | U17: 11 | V17: 9 | W17: 9 | X17: 9 | Y17: 10 | Z17: 11 | AA17: 9 | AB17: 9 | AC17: 9 | AD17: 10 | AE17: 10
A18: 17 | B18: Productos textiles | C18: 1089 | D18: 1156 | E18: 1117 | F18: 1106 | G18: 972 | H18: 866 | I18: 813 | J18: 876 | K18: 983 | L18: 1030 | M18: 1134 | N18: 1175 | O18: 1208 | P18: 1198 | Q18: 1190 | R18: 1230 | S18: 1224 | T18: 1215 | U18: 1186 | V18: 1211 | W18: 1178 | X18: 1141 | Y18: 1092 | Z18: 1043 | AA18: 1036 | AB18: 1056 | AC18: 1087 | AD18: 1074 | AE18: 1063
A19: 18 | B19: Confecciones | C19: 1613 | D19: 1589 | E19: 1555 | F19: 1535 | G19: 1439 | H19: 1317 | I19: 1196 | J19: 1381 | K19: 1575 | L19: 1663 | M19: 1933 | N19: 2030 | O19: 2095 | P19: 2069 | Q19: 2037 | R19: 2004 | S19: 1975 | T19: 1959 | U19: 1985 | V19: 2013 | W19: 1947 | X19: 1884 | Y19: 1758 | Z19: 1639 | AA19: 1525 | AB19: 1482 | AC19: 1603 | AD19: 1596 | AE19: 1535
A20: 19 | B20: Calzado y productos de cuero | C20: 529 | D20: 521 | E20: 500 | F20: 481 | G20: 376 | H20: 343 | I20: 319 | J20: 370 | K20: 421 | L20: 454 | M20: 503 | N20: 529 | O20: 528 | P20: 506 | Q20: 516 | R20: 507 | S20: 492 | T20: 485 | U20: 483 | V20: 478 | W20: 456 | X20: 424 | Y20: 381 | Z20: 355 | AA20: 348 | AB20: 335 | AC20: 359 | AD20: 354 | AE20: 348
A21: 20 | B21: Madera | C21: 247 | D21: 251 | E21: 241 | F21: 246 | G21: 183 | H21: 174 | I21: 156 | J21: 163 | K21: 185 | L21: 201 | M21: 210 | N21: 208 | O21: 215 | P21: 196 | Q21: 194 | R21: 180 | S21: 172 | T21: 155 | U21: 147 | V21: 152 | W21: 145 | X21: 142 | Y21: 136 | Z21: 138 | AA21: 128 | AB21: 131 | AC21: 146 | AD21: 146 | AE21: 154
A22: 21 | B22: Papel | C22: 306 | D22: 318 | E22: 306 | F22: 311 | G22: 272 | H22: 262 | I22: 256 | J22: 271 | K22: 283 | L22: 299 | M22: 296 | N22: 301 | O22: 298 | P22: 288 | Q22: 285 | R22: 277 | S22: 275 | T22: 281 | U22: 278 | V22: 269 | W22: 257 | X22: 247 | Y22: 237 | Z22: 234 | AA22: 228 | AB22: 230 | AC22: 229 | AD22: 217 | AE22: 226
A23: 22 | B23: Edición | C23: 1544 | D23: 1592 | E23: 1646 | F23: 1639 | G23: 1509 | H23: 1424 | I23: 1285 | J23: 1321 | K23: 1408 | L23: 1496 | M23: 1578 | N23: 1644 | O23: 1650 | P23: 1628 | Q23: 1579 | R23: 1581 | S23: 1540 | T23: 1503 | U23: 1465 | V23: 1444 | W23: 1392 | X23: 1336 | Y23: 1276 | Z23: 1200 | AA23: 1145 | AB23: 1080 | AC23: 1060 | AD23: 1020 | AE23: 980
A24: 23 | B24: Productos de petróleo | C24: 35 | D24: 33 | E24: 32 | F24: 33 | G24: 30 | H24: 27 | I24: 25 | J24: 26 | K24: 28 | L24: 26 | M24: 27 | N24: 29 | O24: 28 | P24: 28 | Q24: 28 | R24: 26 | S24: 29 | T24: 29 | U24: 29 | V24: 31 | W24: 27 | X24: 24 | Y24: 25 | Z24: 24 | AA24: 23 | AB24: 24 | AC24: 28 | AD24: 25 | AE24: 26
A25: 24 | B25: Productos químicos | C25: 822 | D25: 850 | E25: 834 | F25: 839 | G25: 711 | H25: 692 | I25: 679 | J25: 712 | K25: 776 | L25: 811 | M25: 814 | N25: 823 | O25: 805 | P25: 806 | Q25: 807 | R25: 793 | S25: 788 | T25: 803 | U25: 793 | V25: 803 | W25: 802 | X25: 787 | Y25: 754 | Z25: 730 | AA25: 732 | AB25: 733 | AC25: 726 | AD25: 710 | AE25: 694
A26: 25 | B26: Productos de caucho y plástico | C26: 717 | D26: 731 | E26: 734 | F26: 719 | G26: 546 | H26: 511 | I26: 486 | J26: 511 | K26: 553 | L26: 587 | M26: 610 | N26: 635 | O26: 633 | P26: 629 | Q26: 634 | R26: 624 | S26: 596 | T26: 609 | U26: 593 | V26: 593 | W26: 575 | X26: 579 | Y26: 556 | Z26: 535 | AA26: 524 | AB26: 544 | AC26: 572 | AD26: 561 | AE26: 565
A27: 26 | B27: Otros minerales no metálicos | C27: 272 | D27: 281 | E27: 274 | F27: 262 | G27: 200 | H27: 202 | I27: 190 | J27: 207 | K27: 209 | L27: 228 | M27: 223 | N27: 239 | O27: 238 | P27: 231 | Q27: 230 | R27: 226 | S27: 225 | T27: 223 | U27: 222 | V27: 220 | W27: 217 | X27: 217 | Y27: 212 | Z27: 215 | AA27: 206 | AB27: 206 | AC27: 206 | AD27: 205 | AE27: 204
... A38: 37 | B38: Reciclamiento de desperdicios y desechos | C38: 17 | D38: 17 | E38: 12 | F38: 13 | G38: 10 | H38: 8 | I38: 10 | J38: 15 | K38: 20 | L38: 21 | M38: 28 | N38: 37 | O38: 33 | P38: 32 | Q38: 41 | R38: 35 | S38: 35 | T38: 32 | U38: 34 | V38: 34 | W38: 31 | X38: 29 | Y38: 29 | Z38: 30 | AA38: 29 | AB38: 33 | AC38: 39 | AD38: 39 | AE38: 41
A39: E | B39: ELECTRICIDAD, GAS Y AGUA | C39: 67 | D39: 68 | E39: 61 | F39: 64 | G39: 52 | H39: 56 | I39: 54 | J39: 52 | K39: 57 | L39: 51 | M39: 52 | N39: 57 | O39: 61 | P39: 63 | Q39: 67 | R39: 69 | S39: 79 | T39: 82 | U39: 75 | V39: 79 | W39: 77 | X39: 91 | Y39: 90 | Z39: 96 | AA39: 100 | AB39: 103 | AC39: 112 | AD39: 108 | AE39: 109
A40: 40 | B40: Electricidad, gas y agua | C40: 55 | D40: 55 | E40: 49 | F40: 52 | G40: 45 | H40: 46 | I40: 46 | J40: 44 | K40: 51 | L40: 46 | M40: 46 | N40: 50 | O40: 54 | P40: 58 | Q40: 61 | R40: 61 | S40: 73 | T40: 76 | U40: 71 | V40: 74 | W40: 72 | X40: 86 | Y40: 86 | Z40: s.d. | AA40: s.d. | AB40: s.d. | AC40: 105 | AD40: 101 | AE40: 102
A41: 41 | B41: Captación, depuración y distribución de agua | C41: 12 | D41: 13 | E41: 12 | F41: 12 | G41: 7 | H41: 10 | I41: 8 | J41: 8 | K41: 6 | L41: 5 | M41: 6 | N41: 7 | O41: 7 | P41: 5 | Q41: 6 | R41: 8 | S41: 6 | T41: 6 | U41: 4 | V41: 5 | W41: 5 | X41: 5 | Y41: 4 | Z41: s.d. | AA41: s.d. | AB41: s.d. | AC41: 7 | AD41: 7 | AE41: 7
A42: F | B42: CONSTRUCCION | C42: 3514 | D42: 3748 | E42: 3798 | F42: 3909 | G42: 3526 | H42: 3130 | I42: 2622 | J42: 3031 | K42: 3576 | L42: 4132 | M42: 4625 | N42: 5066 | O42: 5306 | P42: 5112 | Q42: 5331 | R42: 5463 | S42: 5546 | T42: 5585 | U42: 5533 | V42: 5506 | W42: 5508 | X42: 5658 | Y42: 5753 | Z42: 5634 | AA42: 5249 | AB42: 5298 | AC42: 5562 | AD42: 5635 | AE42: 5436
A43: 45 | B43: Construccion | C43: 3514 | D43: 3748 | E43: 3798 | F43: 3909 | G43: 3526 | H43: 3130 | I43: 2622 | J43: 3031 | K43: 3576 | L43: 4132 | M43: 4625 | N43: 5066 | O43: 5306 | P43: 5112 | Q43: 5331 | R43: 5463 | S43: 5546 | T43: 5585 | U43: 5533 | V43: 5506 | W43: 5508 | X43: 5658 | Y43: 5753 | Z43: 5634 | AA43: 5249 | AB43: 5298 | AC43: 5562 | AD43: 5635 | AE43: 5436
A44: G | B44: COMERCIO AL POR MAYOR Y AL POR MENOR | C44: 20403 | D44: 20608 | E44: 20282 | F44: 19261 | G44: 17242 | H44: 16272 | I44: 15272 | J44: 16971 | K44: 20743 | L44: 22307 | M44: 23791 | N44: 24663 | O44: 25389 | P44: 25566 | Q44: 26170 | R44: 26644 | S44: 26648 | T44: 26709 | U44: 26683 | V44: 27021 | W44: 27570 | X44: 27889 | Y44: 27403 | Z44: 26462 | AA44: 25283 | AB44: 25441 | AC44: 28355 | AD44: 28592 | AE44: 29236
A45: 50 | B45: Vta y reparación de vehículos. vta por menor de combustible | C45: 2657 | D45: 2675 | E45: 2653 | F45: 2519 | G45: 2106 | H45: 2043 | I45: 1937 | J45: 2053 | K45: 2338 | L45: 2441 | M45: 2525 | N45: 2586 | O45: 2635 | P45: 2612 | Q45: 2647 | R45: 2638 | S45: 2635 | T45: 2582 | U45: 2520 | V45: 2545 | W45: 2539 | X45: 2556 | Y45: 2565 | Z45: 2488 | AA45: 2408 | AB45: 2448 | AC45: 2633 | AD45: 2644 | AE45: 2646
A46: 51 | B46: Comercio al por mayor | C46: 6748 | D46: 6845 | E46: 6833 | F46: 6794 | G46: 6264 | H46: 5946 | I46: 5625 | J46: 6265 | K46: 6989 | L46: 7478 | M46: 7900 | N46: 8230 | O46: 8451 | P46: 8537 | Q46: 8739 | R46: 9025 | S46: 9191 | T46: 9290 | U46: 9288 | V46: 9475 | W46: 9617 | X46: 9721 | Y46: 9559 | Z46: 9376 | AA46: 9243 | AB46: 9425 | AC46: 9983 | AD46: 9977 | AE46: 10129
A47: 52 | B47: Comercio al por menor | C47: 10998 | D47: 11088 | E47: 10796 | F47: 9948 | G47: 8872 | H47: 8283 | I47: 7710 | J47: 8653 | K47: 11416 | L47: 12388 | M47: 13366 | N47: 13847 | O47: 14303 | P47: 14417 | Q47: 14784 | R47: 14981 | S47: 14822 | T47: 14837 | U47: 14875 | V47: 15001 | W47: 15414 | X47: 15612 | Y47: 15279 | Z47: 14598 | AA47: 13632 | AB47: 13568 | AC47: 15739 | AD47: 15971 | AE47: 16461
A48: H | B48: HOTELERIA Y RESTAURANTES | C48: 4913 | D48: 4939 | E48: 4680 | F48: 4100 | G48: 3799 | H48: 3606 | I48: 3427 | J48: 3630 | K48: 4825 | L48: 5156 | M48: 5478 | N48: 5768 | O48: 5951 | P48: 6104 | Q48: 6212 | R48: 6375 | S48: 6423 | T48: 6494 | U48: 6508 | V48: 6584 | W48: 6637 | X48: 6772 | Y48: 6835 | Z48: 6731 | AA48: 6031 | AB48: 5981 | AC48: 6954 | AD48: 7224 | AE48: 7372
A49: 55 | B49: Servicios de hoteleria y restaurantes | C49: 4913 | D49: 4939 | E49: 4680 | F49: 4100 | G49: 3799 | H49: 3606 | I49: 3427 | J49: 3630 | K49: 4825 | L49: 5156 | M49: 5478 | N49: 5768 | O49: 5951 | P49: 6104 | Q49: 6212 | R49: 6375 | S49: 6423 | T49: 6494 | U49: 6508 | V49: 6584 | W49: 6637 | X49: 6772 | Y49: 6835 | Z49: 6731 | AA49: 6031 | AB49: 5981 | AC49: 6954 | AD49: 7224 | AE49: 7372
A50: I | B50: SERVICIOS DE TRANSPORTE, DE ALMACENAMIENTO Y DE COMUNICACIONES | C50: 11200 | D50: 13265 | E50: 13735 | F50: 13845 | G50: 13123 | H50: 12264 | I50: 10971 | J50: 10963 | K50: 12092 | L50: 12492 | M50: 12592 | N50: 12850 | O50: 13038 | P50: 12988 | Q50: 12887 | R50: 12858 | S50: 12763 | T50: 12728 | U50: 12510 | V50: 12467 | W50: 12111 | X50: 11818 | Y50: 11240 | Z50: 10388 | AA50: 9113 | AB50: 8421 | AC50: 8396 | AD50: 7986 | AE50: 7609
...

Sheet Resto de Buenos Aires
D1: Volver al índice
A2: RESTO DE BUENOS AIRES
A3: Empresas del sector privado por rama de actividad - Activas en cada año
B4: Ramas de actividad | C4: 1996 | D4: 1997 | E4: 1998 | F4: 1999 | G4: 2000 | H4: 2001 | I4: 2002 | J4: 2003 | K4: 2004 | L4: 2005 | M4: 2006 | N4: 2007 | O4: 2008 | P4: 2009 | Q4: 2010 | R4: 2011 | S4: 2012 | T4: 2013 | U4: 2014 | V4: 2015 | W4: 2016 | X4: 2017 | Y4: 2018 | Z4: 2019 | AA4: 2020 | AB4: 2021 | AC4: 2022 | AD4: 2023 | AE4: 2024
D5: 2º Trim 1996 | F5: 3º Trim 1996 | H5: 4º Trim 1996 | J5: 1º Trim 1997 | L5: 2º Trim 1997 | N5: 3º Trim 1997 | P5: 4º Trim 1997 | R5: 1º Trim 1998
A6: A | B6: AGRICULTURA, GANADERIA, CAZA Y SILVICULTURA | C6: 15965 | D6: 16204 | E6: 16171 | F6: 16280 | G6: 15514 | H6: 14975 | I6: 14834 | J6: 15724 | K6: 16817 | L6: 17805 | M6: 18507 | N6: 18968 | O6: 19290 | P6: 18666 | Q6: 18874 | R6: 19300 | S6: 19024 | T6: 18551 | U6: 18131 | V6: 17598 | W6: 17413 | X6: 17278 | Y6: 16989 | Z6: 16943 | AA6: 16899 | AB6: 17047 | AC6: 17003 | AD6: 16408 | AE6: 16211
A7: 1 | B7: Agricultura y ganaderia | C7: 15912 | D7: 16156 | E7: 16108 | F7: 16216 | G7: 15466 | H7: 14931 | I7: 14793 | J7: 15686 | K7: 16770 | L7: 17757 | M7: 18458 | N7: 18908 | O7: 19231 | P7: 18602 | Q7: 18806 | R7: 19226 | S7: 18951 | T7: 18481 | U7: 18067 | V7: 17527 | W7: 17352 | X7: 17222 | Y7: 16939 | Z7: 16896 | AA7: 16850 | AB7: 17001 | AC7: 16949 | AD7: 16350 | AE7: 16158
A8: 2 | B8: Silvicultura, extracción de madera | C8: 53 | D8: 48 | E8: 63 | F8: 64 | G8: 48 | H8: 44 | I8: 41 | J8: 38 | K8: 47 | L8: 48 | M8: 49 | N8: 60 | O8: 59 | P8: 64 | Q8: 68 | R8: 74 | S8: 73 | T8: 70 | U8: 64 | V8: 71 | W8: 61 | X8: 56 | Y8: 50 | Z8: 47 | AA8: 49 | AB8: 46 | AC8: 54 | AD8: 58 | AE8: 53
A9: B | B9: PESCA Y SERVICIOS CONEXOS | C9: 84 | D9: 96 | E9: 113 | F9: 134 | G9: 168 | H9: 178 | I9: 167 | J9: 165 | K9: 175 | L9: 185 | M9: 195 | N9: 194 | O9: 201 | P9: 205 | Q9: 198 | R9: 197 | S9: 197 | T9: 188 | U9: 180 | V9: 169 | W9: 171 | X9: 163 | Y9: 167 | Z9: 168 | AA9: 165 | AB9: 173 | AC9: 172 | AD9: 165 | AE9: 160
A10: 5 | B10: Pesca y actividades relacionadas con la pesca | C10: 84 | D10: 96 | E10: 113 | F10: 134 | G10: 168 | H10: 178 | I10: 167 | J10: 165 | K10: 175 | L10: 185 | M10: 195 | N10: 194 | O10: 201 | P10: 205 | Q10: 198 | R10: 197 | S10: 197 | T10: 188 | U10: 180 | V10: 169 | W10: 171 | X10: 163 | Y10: 167 | Z10: 168 | AA10: 165 | AB10: 173 | AC10: 172 | AD10: 165 | AE10: 160
A11: C | B11: EXPLOTACION DE MINAS Y CANTERAS | C11: 96 | D11: 101 | E11: 94 | F11: 106 | G11: 96 | H11: 88 | I11: 79 | J11: 79 | K11: 94 | L11: 99 | M11: 112 | N11: 113 | O11: 110 | P11: 108 | Q11: 106 | R11: 111 | S11: 116 | T11: 109 | U11: 108 | V11: 105 | W11: 104 | X11: 111 | Y11: 113 | Z11: 118 | AA11: 114 | AB11: 118 | AC11: 119 | AD11: 118 | AE11: 124
A12: 11 | B12: Extraccion de petroleo crudo y gas natural | C12: 17 | D12: 12 | E12: 15 | F12: 17 | G12: 17 | H12: 17 | I12: 16 | J12: 13 | K12: 15 | L12: 14 | M12: 22 | N12: 21 | O12: 22 | P12: 21 | Q12: 18 | R12: 19 | S12: 20 | T12: 19 | U12: 18 | V12: 17 | W12: 18 | X12: 19 | Y12: 20 | Z12: 20 | AA12: 18 | AB12: 21 | AC12: 25 | AD12: 22 | AE12: 24
A13: 13 | B13: Extraccion de minerales metaliferos | C13: s.d. | D13: s.d. | E13: s.d. | F13: s.d. | G13: s.d. | H13: s.d. | I13: s.d. | J13: s.d. | K13: s.d. | L13: s.d. | M13: s.d. | N13: s.d. | O13: s.d. | P13: s.d. | Q13: s.d. | R13: s.d. | S13: s.d. | T13: s.d. | U13: s.d. | V13: s.d. | W13: s.d. | X13: s.d. | Y13: s.d. | Z13: s.d. | AA13: s.d. | AB13: s.d. | AC13: s.d. | AD13: s.d. | AE13: s.d.
A14: 14 | B14: Explotacion de otras minas y canteras | C14: s.d. | D14: s.d. | E14: s.d. | F14: s.d. | G14: s.d. | H14: s.d. | I14: s.d. | J14: s.d. | K14: s.d. | L14: s.d. | M14: s.d. | N14: s.d. | O14: s.d. | P14: s.d. | Q14: s.d. | R14: s.d. | S14: s.d. | T14: s.d. | U14: s.d. | V14: s.d. | W14: s.d. | X14: s.d. | Y14: s.d. | Z14: s.d. | AA14: s.d. | AB14: s.d. | AC14: s.d. | AD14: s.d. | AE14: s.d.
A15: D | B15: INDUSTRIA MANUFACTURERA | C15: 5886 | D15: 5892 | E15: 5808 | F15: 5826 | G15: 5483 | H15: 5171 | I15: 4903 | J15: 5433 | K15: 6142 | L15: 6590 | M15: 7061 | N15: 7382 | O15: 7659 | P15: 7744 | Q15: 7766 | R15: 7844 | S15: 7995 | T15: 8070 | U15: 8119 | V15: 8239 | W15: 8175 | X15: 8136 | Y15: 7863 | Z15: 7654 | AA15: 7539 | AB15: 7776 | AC15: 8200 | AD15: 8190 | AE15: 8054
A16: 15 | B16: Alimentos | C16: 1931 | D16: 1899 | E16: 1847 | F16: 1786 | G16: 1690 | H16: 1590 | I16: 1532 | J16: 1652 | K16: 1850 | L16: 1944 | M16: 2055 | N16: 2162 | O16: 2324 | P16: 2418 | Q16: 2455 | R16: 2474 | S16: 2523 | T16: 2562 | U16: 2646 | V16: 2684 | W16: 2689 | X16: 2710 | Y16: 2668 | Z16: 2593 | AA16: 2552 | AB16: 2649 | AC16: 2789 | AD16: 2809 | AE16: 2815
A17: 16 | B17: Tabaco | C17: s.d. | D17: s.d. | E17: s.d. | F17: s.d. | G17: s.d. | H17: s.d. | I17: s.d. | J17: s.d. | K17: s.d. | L17: s.d. | M17: s.d. | N17: s.d. | O17: s.d. | P17: s.d. | Q17: s.d. | R17: s.d. | S17: s.d. | T17: s.d. | U17: s.d. | V17: s.d. | W17: s.d. | X17: s.d. | Y17: s.d. | Z17: s.d. | AA17: s.d. | AB17: s.d. | AC17: s.d. | AD17: s.d. | AE17: 4
A18: 17 | B18: Productos textiles | C18: 329 | D18: 337 | E18: 316 | F18: 303 | G18: 292 | H18: 274 | I18: 258 | J18: 285 | K18: 326 | L18: 347 | M18: 380 | N18: 406 | O18: 417 | P18: 412 | Q18: 415 | R18: 425 | S18: 416 | T18: 414 | U18: 423 | V18: 417 | W18: 405 | X18: 401 | Y18: 378 | Z18: 368 | AA18: 355 | AB18: 368 | AC18: 415 | AD18: 426 | AE18: 402
A19: 18 | B19: Confecciones | C19: 355 | D19: 346 | E19: 326 | F19: 309 | G19: 294 | H19: 254 | I19: 231 | J19: 301 | K19: 370 | L19: 410 | M19: 464 | N19: 457 | O19: 452 | P19: 446 | Q19: 422 | R19: 438 | S19: 450 | T19: 441 | U19: 423 | V19: 444 | W19: 430 | X19: 399 | Y19: 365 | Z19: 334 | AA19: 307 | AB19: 302 | AC19: 341 | AD19: 360 | AE19: 336
A20: 19 | B20: Calzado y cuero | C20: 65 | D20: 69 | E20: 64 | F20: 66 | G20: 55 | H20: 53 | I20: 54 | J20: 75 | K20: 86 | L20: 91 | M20: 97 | N20: 90 | O20: 84 | P20: 88 | Q20: 95 | R20: 92 | S20: 98 | T20: 97 | U20: 89 | V20: 90 | W20: 85 | X20: 80 | Y20: 72 | Z20: 69 | AA20: 67 | AB20: 69 | AC20: 80 | AD20: 75 | AE20: 72
A21: 20 | B21: Madera | C21: 324 | D21: 320 | E21: 308 | F21: 297 | G21: 279 | H21: 264 | I21: 236 | J21: 255 | K21: 299 | L21: 339 | M21: 350 | N21: 361 | O21: 363 | P21: 356 | Q21: 346 | R21: 344 | S21: 341 | T21: 335 | U21: 327 | V21: 330 | W21: 314 | X21: 304 | Y21: 285 | Z21: 275 | AA21: 270 | AB21: 268 | AC21: 286 | AD21: 268 | AE21: 248
A22: 21 | B22: Papel | C22: 63 | D22: 62 | E22: 60 | F22: 65 | G22: 64 | H22: 61 | I22: 63 | J22: 67 | K22: 75 | L22: 76 | M22: 81 | N22: 84 | O22: 84 | P22: 88 | Q22: 84 | R22: 85 | S22: 84 | T22: 89 | U22: 94 | V22: 92 | W22: 97 | X22: 92 | Y22: 94 | Z22: 96 | AA22: 96 | AB22: 105 | AC22: 99 | AD22: 88 | AE22: 90
A23: 22 | B23: Edición | C23: 391 | D23: 387 | E23: 401 | F23: 412 | G23: 394 | H23: 371 | I23: 348 | J23: 375 | K23: 418 | L23: 443 | M23: 480 | N23: 496 | O23: 519 | P23: 521 | Q23: 515 | R23: 511 | S23: 516 | T23: 499 | U23: 493 | V23: 484 | W23: 479 | X23: 474 | Y23: 440 | Z23: 412 | AA23: 391 | AB23: 377 | AC23: 363 | AD23: 352 | AE23: 337
A24: 23 | B24: Productos de petróleo | C24: 16 | D24: 16 | E24: 16 | F24: 18 | G24: 16 | H24: 15 | I24: 15 | J24: 18 | K24: 17 | L24: 17 | M24: 18 | N24: 19 | O24: 19 | P24: 21 | Q24: 21 | R24: 22 | S24: 22 | T24: 20 | U24: 19 | V24: 18 | W24: 19 | X24: 21 | Y24: 19 | Z24: 20 | AA24: 21 | AB24: 22 | AC24: 24 | AD24: 22 | AE24: 22
A25: 24 | B25: Productos químicos | C25: 274 | D25: 272 | E25: 275 | F25: 314 | G25: 321 | H25: 315 | I25: 297 | J25: 317 | K25: 327 | L25: 340 | M25: 358 | N25: 361 | O25: 374 | P25: 364 | Q25: 371 | R25: 379 | S25: 391 | T25: 414 | U25: 412 | V25: 419 | W25: 430 | X25: 431 | Y25: 421 | Z25: 425 | AA25: 425 | AB25: 428 | AC25: 443 | AD25: 443 | AE25: 451
A26: 25 | B26: Productos de caucho y plástico | C26: 181 | D26: 179 | E26: 200 | F26: 229 | G26: 216 | H26: 217 | I26: 216 | J26: 228 | K26: 254 | L26: 265 | M26: 281 | N26: 292 | O26: 302 | P26: 297 | Q26: 293 | R26: 293 | S26: 306 | T26: 315 | U26: 330 | V26: 348 | W26: 348 | X26: 348 | Y26: 338 | Z26: 323 | AA26: 338 | AB26: 352 | AC26: 384 | AD26: 372 | AE26: 372
A27: 26 | B27: Otros minerales no metálicos | C27: 357 | D27: 361 | E27: 361 | F27: 354 | G27: 325 | H27: 286 | I27: 268 | J27: 276 | K27: 294 | L27: 318 | M27: 342 | N27: 357 | O27: 365 | P27: 366 | Q27: 352 | R27: 351 | S27: 366 | T27: 374 | U27: 377 | V27: 379 | W27: 365 | X27: 363 | Y27: 358 | Z27: 359 | AA27: 359 | AB27: 381 | AC27: 399 | AD27: 380 | AE27: 364
A28: 27 | B28: Metales comunes | C28: 135 | D28: 140 | E28: 139 | F28: 136 | G28: 112 | H28: 106 | I28: 103 | J28: 113 | K28: 120 | L28: 138 | M28: 138 | N28: 135 | O28: 140 | P28: 129 | Q28: 136 | R28: 134 | S28: 134 | T28: 138 | U28: 137 | V28: 135 | W28: 135 | X28: 131 | Y28: 118 | Z28: 123 | AA28: 122 | AB28: 123 | AC28: 133 | AD28: 139 | AE28: 136
A29: 28 | B29: Otros productos de metal | C29: 615 | D29: 647 | E29: 633 | F29: 666 | G29: 639 | H29: 609 | I29: 567 | J29: 636 | K29: 750 | L29: 816 | M29: 874 | N29: 957 | O29: 989 | P29: 967 | Q29: 985 | R29: 1028 | S29: 1069 | T29: 1068 | U29: 1058 | V29: 1077 | W29: 1075 | X29: 1091 | Y29: 1040 | Z29: 1009 | AA29: 992 | AB29: 1011 | AC29: 1057 | AD29: 1055 | AE29: 1048
A30: 29 | B30: Maquinaria y equipo | C30: 263 | D30: 269 | E30: 269 | F30: 276 | G30: 243 | H30: 233 | I30: 228 | J30: 264 | K30: 299 | L30: 326 | M30: 351 | N30: 356 | O30: 350 | P30: 354 | Q30: 355 | R30: 364 | S30: 374 | T30: 385 | U30: 386 | V30: 389 | W30: 390 | X30: 403 | Y30: 382 | Z30: 373 | AA30: 375 | AB30: 395 | AC30: 406 | AD30: 398 | AE30: 380
A31: 30 | B31: Maquinaria de oficina | C31: s.d. | D31: s.d. | E31: s.d. | F31: s.d. | G31: s.d. | H31: 5 | I31: 5 | J31: 7 | K31: 7 | L31: 10 | M31: 10 | N31: 11 | O31: 11 | P31: 9 | Q31: 9 | R31: 11 | S31: s.d. | T31: s.d. | U31: s.d. | V31: s.d. | W31: s.d. | X31: s.d. | Y31: s.d. | Z31: 8 | AA31: 8 | AB31: 9 | AC31: s.d. | AD31: s.d. | AE31: 12
A32: 31 | B32: Aparatos eléctricos | C32: 83 | D32: 86 | E32: 83 | F32: 86 | G32: 78 | H32: 75 | I32: 63 | J32: 71 | K32: 78 | L32: 80 | M32: 93 | N32: 98 | O32: 104 | P32: 107 | Q32: 110 | R32: 113 | S32: 110 | T32: 112 | U32: 117 | V32: 121 | W32: 116 | X32: 114 | Y32: 114 | Z32: 110 | AA32: 107 | AB32: 113 | AC32: 115 | AD32: 111 | AE32: 114
A33: 32 | B33: Radio y televisión | C33: 16 | D33: 13 | E33: 12 | F33: 13 | G33: 11 | H33: s.d. | I33: s.d. | J33: s.d. | K33: s.d. | L33: s.d. | M33: s.d. | N33: s.d. | O33: s.d. | P33: s.d. | Q33: s.d. | R33: s.d. | S33: 10 | T33: 9 | U33: 11 | V33: 12 | W33: 12 | X33: 13 | Y33: 12 | Z33: s.d. | AA33: s.d. | AB33: s.d. | AC33: 10 | AD33: 12 | AE33: 12
A34: 33 | B34: Instrumentos médicos | C34: 33 | D34: 29 | E34: 28 | F34: 29 | G34: 27 | H34: 27 | I34: 26 | J34: 34 | K34: 38 | L34: 43 | M34: 44 | N34: 46 | O34: 43 | P34: 40 | Q34: 36 | R34: 38 | S34: 40 | T34: 41 | U34: 43 | V34: 49 | W34: 50 | X34: 45 | Y34: 45 | Z34: 44 | AA34: 44 | AB34: 47 | AC34: 52 | AD34: 47 | AE34: 50
A35: 34 | B35: Automotores | C35: 132 | D35: 137 | E35: 145 | F35: 146 | G35: 142 | H35: 144 | I35: 135 | J35: 146 | K35: 163 | L35: 176 | M35: 190 | N35: 195 | O35: 198 | P35: 198 | Q35: 207 | R35: 201 | S35: 197 | T35: 203 | U35: 199 | V35: 207 | W35: 207 | X35: 205 | Y35: 191 | Z35: 186 | AA35: 186 | AB35: 199 | AC35: 210 | AD35: 211 | AE35: 196
A36: 35 | B36: Otros equipo de transporte | C36: 59 | D36: 61 | E36: 55 | F36: 63 | G36: 52 | H36: 55 | I36: 55 | J36: 73 | K36: 82 | L36: 97 | M36: 105 | N36: 115 | O36: 116 | P36: 129 | Q36: 132 | R36: 132 | S36: 137 | T36: 139 | U36: 138 | V36: 138 | W36: 148 | X36: 148 | Y36: 155 | Z36: 157 | AA36: 171 | AB36: 198 | AC36: 210 | AD36: 209 | AE36: 205
A37: 36 | B37: Muebles | C37: 241 | D37: 238 | E37: 243 | F37: 227 | G37: 207 | H37: 190 | I37: 178 | J37: 204 | K37: 249 | L37: 276 | M37: 307 | N37: 338 | O37: 359 | P37: 382 | Q37: 380 | R37: 368 | S37: 360 | T37: 362 | U37: 344 | V37: 352 | W37: 325 | X37: 314 | Y37: 315 | Z37: 308 | AA37: 295 | AB37: 304 | AC37: 332 | AD37: 357 | AE37: 351
A38: 37 | B38: Reciclamiento de desperdicios y desechos | C38: 16 | D38: 16 | E38: 20 | F38: 21 | G38: 16 | H38: 17 | I38: 19 | J38: 25 | K38: 28 | L38: 27 | M38: 32 | N38: 32 | O38: 32 | P38: 36 | Q38: 34 | R38: 31 | S38: 39 | T38: 41 | U38: 43 | V38: 43 | W38: 45 | X38: 39 | Y38: 42 | Z38: 46 | AA38: 44 | AB38: 42 | AC38: 41 | AD38: 41 | AE38: 37
A39: E | B39: ELECTRICIDAD, GAS Y AGUA | C39: 273 | D39: 269 | E39: 278 | F39: 282 | G39: 274 | H39: 275 | I39: 270 | J39: 271 | K39: 275 | L39: 275 | M39: 277 | N39: 274 | O39: 275 | P39: 279 | Q39: 284 | R39: 286 | S39: 287 | T39: 292 | U39: 287 | V39: 290 | W39: 291 | X39: 296 | Y39: 290 | Z39: 296 | AA39: 294 | AB39: 299 | AC39: 302 | AD39: 299 | AE39: 295
A40: 40 | B40: Electricidad, gas y agua | C40: 222 | D40: 221 | E40: 228 | F40: 232 | G40: 223 | H40: 224 | I40: 219 | J40: 219 | K40: 221 | L40: 221 | M40: 221 | N40: 218 | O40: 218 | P40: 223 | Q40: 226 | R40: 228 | S40: 229 | T40: 231 | U40: 228 | V40: 232 | W40: 233 | X40: 237 | Y40: 234 | Z40: 236 | AA40: 236 | AB40: 241 | AC40: 244 | AD40: 242 | AE40: 240
...

Sheet Catamarca
D1: Volver al índice
A2: CATAMARCA
A3: Empresas del sector privado por rama de actividad - Activas en cada año
B4: Ramas de actividad | C4: 1996 | D4: 1997 | E4: 1998 | F4: 1999 | G4: 2000 | H4: 2001 | I4: 2002 | J4: 2003 | K4: 2004 | L4: 2005 | M4: 2006 | N4: 2007 | O4: 2008 | P4: 2009 | Q4: 2010 | R4: 2011 | S4: 2012 | T4: 2013 | U4: 2014 | V4: 2015 | W4: 2016 | X4: 2017 | Y4: 2018 | Z4: 2019 | AA4: 2020 | AB4: 2021 | AC4: 2022 | AD4: 2023 | AE4: 2024
D5: 2º Trim 1996 | F5: 3º Trim 1996 | H5: 4º Trim 1996 | J5: 1º Trim 1997 | L5: 2º Trim 1997 | N5: 3º Trim 1997 | P5: 4º Trim 1997 | R5: 1º Trim 1998
A6: A | B6: AGRICULTURA, GANADERIA, CAZA Y SILVICULTURA | C6: 263 | D6: 278 | E6: 298 | F6: 312 | G6: 298 | H6: 297 | I6: 266 | J6: 266 | K6: 271 | L6: 285 | M6: 310 | N6: 324 | O6: 328 | P6: 320 | Q6: 320 | R6: 322 | S6: 302 | T6: 309 | U6: 297 | V6: 290 | W6: 274 | X6: 284 | Y6: 261 | Z6: 249 | AA6: 239 | AB6: 241 | AC6: 249 | AD6: 240 | AE6: 225
A7: 1 | B7: Agricultura y ganaderia | C7: 257 | D7: 272 | E7: 290 | F7: 304 | G7: 291 | H7: 290 | I7: 259 | J7: 260 | K7: 265 | L7: 278 | M7: 303 | N7: 317 | O7: 321 | P7: 314 | Q7: 314 | R7: 316 | S7: 295 | T7: 301 | U7: 290 | V7: 283 | W7: 268 | X7: 279 | Y7: 257 | Z7: s.d. | AA7: s.d. | AB7: s.d. | AC7: s.d. | AD7: 235 | AE7: 221
A8: 2 | B8: Silvicultura, extracción de madera | C8: 6 | D8: 6 | E8: 8 | F8: 8 | G8: 7 | H8: 7 | I8: 7 | J8: 6 | K8: 6 | L8: 7 | M8: 7 | N8: 7 | O8: 7 | P8: 6 | Q8: 6 | R8: 6 | S8: 7 | T8: 8 | U8: 7 | V8: 7 | W8: 6 | X8: 5 | Y8: 4 | Z8: s.d. | AA8: s.d. | AB8: s.d. | AC8: s.d. | AD8: 5 | AE8: 4
A9: B | B9: PESCA Y SERVICIOS CONEXOS | C9: 0 | D9: 0 | E9: 0 | F9: 0 | G9: 0 | H9: 0 | I9: 0 | J9: 0 | K9: 0 | L9: 0 | M9: 0 | N9: 0 | O9: 0 | P9: 0 | Q9: 0 | R9: 0 | S9: 0 | T9: 0 | U9: 0 | V9: 0 | W9: 0 | X9: 0 | Y9: 0 | Z9: 0 | AA9: 0 | AB9: 0 | AC9: 0 | AD9: 0 | AE9: 0
A10: 5 | B10: Pesca y actividades relacionadas con la pesca | C10: 0 | D10: 0 | E10: 0 | F10: 0 | G10: 0 | H10: 0 | I10: 0 | J10: 0 | K10: 0 | L10: 0 | M10: 0 | N10: 0 | O10: 0 | P10: 0 | Q10: 0 | R10: 0 | S10: 0 | T10: 0 | U10: 0 | V10: 0 | W10: 0 | X10: 0 | Y10: 0 | Z10: 0 | AA10: 0 | AB10: 0 | AC10: 0 | AD10: 0 | AE10: 0
A11: C | B11: EXPLOTACION DE MINAS Y CANTERAS | C11: 19 | D11: 19 | E11: 19 | F11: 22 | G11: 14 | H11: 17 | I11: 11 | J11: 16 | K11: 15 | L11: 17 | M11: 20 | N11: 22 | O11: 24 | P11: 22 | Q11: 22 | R11: 18 | S11: 19 | T11: 21 | U11: 17 | V11: 15 | W11: 13 | X11: 17 | Y11: 18 | Z11: 18 | AA11: 18 | AB11: 18 | AC11: 23 | AD11: 28 | AE11: 31
A12: 11 | B12: Extraccion de petroleo crudo y gas natural | C12: s.d. | D12: s.d. | E12: 7 | F12: 8 | G12: s.d. | H12: s.d. | I12: s.d. | J12: s.d. | K12: s.d. | L12: s.d. | M12: s.d. | N12: s.d. | O12: s.d. | P12: s.d. | Q12: s.d. | R12: s.d. | S12: s.d. | T12: s.d. | U12: s.d. | V12: s.d. | W12: s.d. | X12: s.d. | Y12: s.d. | Z12: s.d. | AA12: s.d. | AB12: s.d. | AC12: s.d. | AD12: s.d. | AE12: s.d.
A13: 13 | B13: Extraccion de minerales metaliferos | C13: s.d. | D13: s.d. | E13: s.d. | F13: s.d. | G13: s.d. | H13: s.d. | I13: s.d. | J13: s.d. | K13: s.d. | L13: s.d. | M13: s.d. | N13: s.d. | O13: 4 | P13: s.d. | Q13: 4 | R13: s.d. | S13: s.d. | T13: s.d. | U13: s.d. | V13: s.d. | W13: s.d. | X13: s.d. | Y13: s.d. | Z13: s.d. | AA13: s.d. | AB13: s.d. | AC13: s.d. | AD13: 7 | AE13: 10
A14: 14 | B14: Explotacion de otras minas y canteras | C14: 13 | D14: 14 | E14: s.d. | F14: s.d. | G14: 9 | H14: 11 | I14: 9 | J14: 13 | K14: 12 | L14: 14 | M14: 16 | N14: 17 | O14: s.d. | P14: 18 | Q14: s.d. | R14: 15 | S14: 16 | T14: 15 | U14: 13 | V14: 13 | W14: 12 | X14: 15 | Y14: 15 | Z14: 12 | AA14: 14 | AB14: 15 | AC14: 18 | AD14: s.d. | AE14: s.d.
A15: D | B15: INDUSTRIA MANUFACTURERA | C15: 253 | D15: 268 | E15: 253 | F15: 256 | G15: 229 | H15: 226 | I15: 208 | J15: 226 | K15: 209 | L15: 222 | M15: 236 | N15: 266 | O15: 257 | P15: 247 | Q15: 260 | R15: 256 | S15: 263 | T15: 261 | U15: 265 | V15: 276 | W15: 264 | X15: 279 | Y15: 256 | Z15: 244 | AA15: 240 | AB15: 246 | AC15: 272 | AD15: 297 | AE15: 272
A16: 15 | B16: Alimentos | C16: 90 | D16: 98 | E16: 104 | F16: 105 | G16: 92 | H16: 88 | I16: 91 | J16: 103 | K16: 95 | L16: 104 | M16: 103 | N16: 117 | O16: 118 | P16: 119 | Q16: 126 | R16: 123 | S16: 125 | T16: 124 | U16: 123 | V16: 133 | W16: 123 | X16: 125 | Y16: 116 | Z16: 111 | AA16: 109 | AB16: 109 | AC16: 122 | AD16: 129 | AE16: 130
A17: 16 | B17: Tabaco | C17: s.d. | D17: s.d. | E17: s.d. | F17: s.d. | G17: s.d. | H17: s.d. | I17: s.d. | J17: s.d. | K17: s.d. | L17: s.d. | M17: s.d. | N17: s.d. | O17: s.d. | P17: s.d. | Q17: s.d. | R17: s.d. | S17: s.d. | T17: s.d. | U17: s.d. | V17: s.d. | W17: s.d. | X17: s.d. | Y17: s.d. | Z17: s.d. | AA17: s.d. | AB17: s.d. | AC17: s.d. | AD17: s.d. | AE17: s.d.
A18: 17 | B18: Productos textiles | C18: 14 | D18: 17 | E18: 15 | F18: 15 | G18: 13 | H18: 13 | I18: 13 | J18: 14 | K18: 13 | L18: 15 | M18: 14 | N18: 14 | O18: 14 | P18: 12 | Q18: 12 | R18: 12 | S18: 9 | T18: 10 | U18: 12 | V18: 11 | W18: 12 | X18: 13 | Y18: 13 | Z18: 15 | AA18: 14 | AB18: 17 | AC18: 20 | AD18: 21 | AE18: 20
A19: 18 | B19: Confecciones | C19: 15 | D19: 16 | E19: 14 | F19: 14 | G19: 14 | H19: 16 | I19: 13 | J19: 15 | K19: 14 | L19: 12 | M19: 13 | N19: 13 | O19: 14 | P19: 9 | Q19: 11 | R19: 12 | S19: 14 | T19: 14 | U19: 14 | V19: 14 | W19: 15 | X19: 13 | Y19: 12 | Z19: 13 | AA19: 12 | AB19: 14 | AC19: 17 | AD19: 18 | AE19: 18
A20: 19 | B20: Calzado y productos de cuero | C20: 6 | D20: 8 | E20: 5 | F20: 5 | G20: 6 | H20: 5 | I20: 5 | J20: 6 | K20: 7 | L20: 6 | M20: 7 | N20: 10 | O20: 9 | P20: 7 | Q20: 9 | R20: 10 | S20: 11 | T20: 6 | U20: 6 | V20: 4 | W20: 4 | X20: 5 | Y20: 5 | Z20: 5 | AA20: 5 | AB20: 6 | AC20: 8 | AD20: 8 | AE20: 7
A21: 20 | B21: Madera | C21: 11 | D21: 10 | E21: 11 | F21: 7 | G21: 7 | H21: 7 | I21: 7 | J21: 8 | K21: 7 | L21: 6 | M21: 9 | N21: 11 | O21: 12 | P21: 9 | Q21: 9 | R21: 8 | S21: 9 | T21: 9 | U21: 9 | V21: 9 | W21: 8 | X21: 8 | Y21: 8 | Z21: 7 | AA21: 5 | AB21: 5 | AC21: 7 | AD21: 5 | AE21: 6
A22: 21 | B22: Papel | C22: 5 | D22: 7 | E22: 6 | F22: 5 | G22: 4 | H22: s.d. | I22: s.d. | J22: 6 | K22: 4 | L22: s.d. | M22: s.d. | N22: s.d. | O22: s.d. | P22: s.d. | Q22: s.d. | R22: s.d. | S22: 5 | T22: 4 | U22: 4 | V22: 4 | W22: 4 | X22: 4 | Y22: 4 | Z22: 5 | AA22: s.d. | AB22: 4 | AC22: s.d. | AD22: s.d. | AE22: s.d.
A23: 22 | B23: Edición | C23: 18 | D23: 17 | E23: 17 | F23: 18 | G23: 18 | H23: 15 | I23: 12 | J23: 15 | K23: 13 | L23: 12 | M23: 12 | N23: 16 | O23: 20 | P23: 19 | Q23: 20 | R23: 19 | S23: 18 | T23: 22 | U23: 22 | V23: 23 | W23: 24 | X23: 25 | Y23: 19 | Z23: 15 | AA23: 15 | AB23: 17 | AC23: 16 | AD23: 20 | AE23: 18
A24: 23 | B24: Productos de petróleo | C24: s.d. | D24: s.d. | E24: s.d. | F24: s.d. | G24: s.d. | H24: s.d. | I24: s.d. | J24: s.d. | K24: s.d. | L24: s.d. | M24: s.d. | N24: s.d. | O24: s.d. | P24: s.d. | Q24: s.d. | R24: s.d. | S24: s.d. | T24: s.d. | U24: s.d. | V24: s.d. | W24: s.d. | X24: s.d. | Y24: s.d. | Z24: s.d. | AA24: s.d. | AB24: s.d. | AC24: s.d. | AD24: s.d. | AE24: s.d.
A25: 24 | B25: Productos químicos | C25: 28 | D25: 24 | E25: 20 | F25: 23 | G25: 21 | H25: 25 | I25: 20 | J25: 20 | K25: 18 | L25: 22 | M25: 23 | N25: 25 | O25: 21 | P25: 19 | Q25: 22 | R25: 19 | S25: 22 | T25: 22 | U25: 24 | V25: 23 | W25: 22 | X25: 21 | Y25: 21 | Z25: 19 | AA25: 19 | AB25: 21 | AC25: 18 | AD25: 19 | AE25: 16
A26: 25 | B26: Productos de caucho y plástico | C26: 8 | D26: 8 | E26: 5 | F26: 7 | G26: 5 | H26: 4 | I26: 4 | J26: s.d. | K26: s.d. | L26: s.d. | M26: 4 | N26: 5 | O26: s.d. | P26: 6 | Q26: 5 | R26: 4 | S26: 5 | T26: s.d. | U26: s.d. | V26: 4 | W26: s.d. | X26: s.d. | Y26: s.d. | Z26: s.d. | AA26: s.d. | AB26: s.d. | AC26: s.d. | AD26: s.d. | AE26: s.d.
A27: 26 | B27: Otros minerales no metálicos | C27: 9 | D27: 11 | E27: 10 | F27: 10 | G27: 9 | H27: 10 | I27: 7 | J27: 9 | K27: 7 | L27: 8 | M27: 7 | N27: 9 | O27: 7 | P27: 8 | Q27: 9 | R27: 12 | S27: 11 | T27: 12 | U27: 11 | V27: 10 | W27: 11 | X27: 13 | Y27: 11 | Z27: 11 | AA27: 10 | AB27: 11 | AC27: 10 | AD27: 10 | AE27: 9
A28: 27 | B28: Metales comunes | C28: s.d. | D28: s.d. | E28: s.d. | F28: s.d. | G28: s.d. | H28: s.d. | I28: s.d. | J28: s.d. | K28: s.d. | L28: s.d. | M28: s.d. | N28: s.d. | O28: s.d. | P28: s.d. | Q28: s.d. | R28: s.d. | S28: s.d. | T28: s.d. | U28: 4 | V28: 4 | W28: s.d. | X28: s.d. | Y28: s.d. | Z28: s.d. | AA28: s.d. | AB28: s.d. | AC28: s.d. | AD28: s.d. | AE28: s.d.
A29: 28 | B29: Otros productos de metal | C29: 13 | D29: 12 | E29: 11 | F29: 11 | G29: 10 | H29: 11 | I29: 8 | J29: 7 | K29: 7 | L29: 9 | M29: 11 | N29: 9 | O29: 8 | P29: 9 | Q29: 9 | R29: 9 | S29: 9 | T29: 9 | U29: 9 | V29: 10 | W29: 9 | X29: 11 | Y29: 10 | Z29: 8 | AA29: 12 | AB29: 10 | AC29: 18 | AD29: 22 | AE29: 16
A30: 29 | B30: Maquinaria y equipo | C30: 13 | D30: 13 | E30: 12 | F30: 13 | G30: 13 | H30: 16 | I30: 14 | J30: 11 | K30: 11 | L30: 9 | M30: 11 | N30: 10 | O30: 10 | P30: 9 | Q30: 9 | R30: 12 | S30: 11 | T30: 8 | U30: 8 | V30: 8 | W30: 7 | X30: 8 | Y30: 7 | Z30: 9 | AA30: 8 | AB30: 6 | AC30: 7 | AD30: 9 | AE30: 7
A31: 30 | B31: Maquinaria de oficina | C31: s.d. | D31: s.d. | E31: s.d. | F31: s.d. | G31: s.d. | H31: s.d. | I31: s.d. | J31: s.d. | K31: s.d. | L31: s.d. | M31: s.d. | N31: s.d. | O31: s.d. | P31: s.d. | Q31: s.d. | R31: s.d. | S31: s.d. | T31: s.d. | U31: s.d. | V31: s.d. | W31: s.d. | X31: s.d. | Y31: s.d. | Z31: s.d. | AA31: s.d. | AB31: s.d. | AC31: s.d. | AD31: s.d. | AE31: s.d.
A32: 31 | B32: Aparatos eléctricos | C32: s.d. | D32: s.d. | E32: s.d. | F32: s.d. | G32: s.d. | H32: s.d. | I32: s.d. | J32: s.d. | K32: s.d. | L32: s.d. | M32: s.d. | N32: s.d. | O32: s.d. | P32: s.d. | Q32: s.d. | R32: s.d. | S32: s.d. | T32: s.d. | U32: s.d. | V32: s.d. | W32: s.d. | X32: 4 | Y32: 6 | Z32: 5 | AA32: 5 | AB32: 4 | AC32: 4 | AD32: 4 | AE32: s.d.
A33: 32 | B33: Radio y televisión | C33: s.d. | D33: s.d. | E33: s.d. | F33: s.d. | G33: s.d. | H33: s.d. | I33: s.d. | J33: s.d. | K33: s.d. | L33: s.d. | M33: s.d. | N33: s.d. | O33: s.d. | P33: s.d. | Q33: s.d. | R33: s.d. | S33: s.d. | T33: s.d. | U33: s.d. | V33: s.d. | W33: s.d. | X33: s.d. | Y33: s.d. | Z33: s.d. | AA33: s.d. | AB33: s.d. | AC33: s.d. | AD33: s.d. | AE33: s.d.
A34: 33 | B34: Instrumentos médicos | C34: s.d. | D34: s.d. | E34: s.d. | F34: s.d. | G34: s.d. | H34: s.d. | I34: s.d. | J34: s.d. | K34: s.d. | L34: s.d. | M34: s.d. | N34: s.d. | O34: s.d. | P34: s.d. | Q34: s.d. | R34: s.d. | S34: s.d. | T34: s.d. | U34: s.d. | V34: s.d. | W34: s.d. | X34: s.d. | Y34: s.d. | Z34: s.d. | AA34: s.d. | AB34: s.d. | AC34: s.d. | AD34: s.d. | AE34: s.d.
A35: 34 | B35: Automotores | C35: s.d. | D35: s.d. | E35: s.d. | F35: s.d. | G35: s.d. | H35: s.d. | I35: s.d. | J35: s.d. | K35: s.d. | L35: s.d. | M35: s.d. | N35: s.d. | O35: s.d. | P35: s.d. | Q35: s.d. | R35: s.d. | S35: s.d. | T35: s.d. | U35: s.d. | V35: s.d. | W35: s.d. | X35: s.d. | Y35: s.d. | Z35: s.d. | AA35: s.d. | AB35: s.d. | AC35: s.d. | AD35: s.d. | AE35: s.d.
A36: 35 | B36: Otros equipo de transporte | C36: s.d. | D36: s.d. | E36: s.d. | F36: s.d. | G36: s.d. | H36: s.d. | I36: s.d. | J36: s.d. | K36: s.d. | L36: s.d. | M36: s.d. | N36: s.d. | O36: s.d. | P36: s.d. | Q36: s.d. | R36: s.d. | S36: s.d. | T36: s.d. | U36: s.d. | V36: s.d. | W36: s.d. | X36: s.d. | Y36: s.d. | Z36: s.d. | AA36: s.d. | AB36: s.d. | AC36: s.d. | AD36: 4 | AE36: s.d.
