Workbook

Sheet anual
A1: provincia | B1: variable | C1: 1993 | D1: 1994 | E1: 1995 | F1: 1996 | G1: 1997 | H1: 1998 | I1: 1999 | J1: 2000 | K1: 2001 | L1: 2002 | M1: 2003 | N1: 2004 | O1: 2005 | P1: 2006 | Q1: 2007 | R1: 2008 | S1: 2009 | T1: 2010 | U1: 2011 | V1: 2012 | W1: 2013 | X1: 2014 | Y1: 2015 | Z1: 2016 | AA1: 2017 | AB1: 2018 | AC1: 2019 | AD1: 2020 | AE1: 2021 | AF1: 2022 | AG1: 2023 | AH1: 2024 | AI1: 2025
A2: Buenos Aires | B2: pob | AF2: 17523996
A3: CABA | B3: pob | AF3: 3121707
A4: Catamarca | B4: pob | AF4: 429562
A5: Chaco | B5: pob | AF5: 1129606
A6: Chubut | B6: pob | AF6: 592621
A7: Córdoba | B7: pob | AF7: 3840905
A8: Corrientes | B8: pob | AF8: 1212696
A9: Entre Ríos | B9: pob | AF9: 1425578
A10: Formosa | B10: pob | AF10: 607419
A11: Jujuy | B11: pob | AF11: 811611
A12: La Pampa | B12: pob | AF12: 361859
A13: La Rioja | B13: pob | AF13: 383865
... A25: Tucumán | B25: pob | AF25: 1731820
A26: Buenos Aires | B26: vab | N26: 85706.939 | O26: 93498.594 | P26: 101670.21 | Q26: 112133.3 | R26: 117261.87 | S26: 114087.18 | T26: 120846.77 | U26: 126825.76 | V26: 124949.92 | W26: 125041.9 | X26: 122464.18 | Y26: 124247.15 | Z26: 123199.88 | AA26: 125973.65 | AB26: 124075.63 | AC26: 118237.39 | AD26: 103834.72 | AE26: 113402.66 | AF26: 119077.26 | AG26: 119523.88
A27: CABA | B27: vab | N27: 131865.79 | O27: 144239 | P27: 154667.8 | Q27: 165764.35 | R27: 173660.63 | S27: 162677.78 | T27: 182196.42 | U27: 193596.88 | V27: 192649.04 | W27: 196324.76 | X27: 189466.14 | Y27: 195435.29 | Z27: 191324.34 | AA27: 196195.45 | AB27: 189876.09 | AC27: 185100.15 | AD27: 167866.01 | AE27: 186661.14 | AF27: 196714.6 | AG27: 193076.18
A28: Catamarca | B28: vab | N28: 3857.9592 | O28: 4349.6119 | P28: 4585.2407 | Q28: 4733.5821 | R28: 4554.0306 | S28: 4155.2544 | T28: 4255.8601 | U28: 4227.8942 | V28: 4321.4966 | W28: 4132.6768 | X28: 4257.0025 | Y28: 3848.4471 | Z28: 3850.0663 | AA28: 3789.7919 | AB28: 3615.6886 | AC28: 3268.2448 | AD28: 2943.7234 | AE28: 3427.6514 | AF28: 3815.2976 | AG28: 4091.1576
A29: Chaco | B29: vab | N29: 32365.857 | O29: 37646.15 | P29: 39981.301 | Q29: 45313.503 | R29: 46362.132 | S29: 42126.604 | T29: 47510.276 | U29: 49640.755 | V29: 47356.028 | W29: 50887.616 | X29: 50214.053 | Y29: 52202.432 | Z29: 51381.021 | AA29: 52454.129 | AB29: 49000.602 | AC29: 50159.299 | AD29: 44623.413 | AE29: 50042.177 | AF29: 51617.312 | AG29: 47892.307
A30: Chubut | B30: vab | N30: 4777.1032 | O30: 5418.7952 | P30: 5701.3213 | Q30: 6082.0508 | R30: 6338.2549 | S30: 6140.4811 | T30: 6489.8286 | U30: 7120.276 | V30: 7156.2017 | W30: 7340.9991 | X30: 7367.167 | Y30: 7568.6871 | Z30: 7413.7433 | AA30: 7769.9566 | AB30: 7861.2562 | AC30: 7578.9389 | AD30: 6917.2729 | AE30: 7557.4076 | AF30: 7705.7653 | AG30: 7868.3268
A31: Córdoba | B31: vab | N31: 5596.9167 | O31: 6253.3364 | P31: 6855.5332 | Q31: 7470.8879 | R31: 7888.9325 | S31: 7512.6511 | T31: 8460.0524 | U31: 9350.0285 | V31: 8518.8629 | W31: 8938.5958 | X31: 9649.5906 | Y31: 9540.6107 | Z31: 9426.653 | AA31: 9798.3584 | AB31: 9672.0486 | AC31: 9147.1866 | AD31: 8556.2971 | AE31: 9150.9198 | AF31: 9866.3612 | AG31: 9606.2519
A32: Corrientes | B32: vab | N32: 9546.8409 | O32: 9965.7352 | P32: 10999.404 | Q32: 11203.245 | R32: 11325.996 | S32: 10718.519 | T32: 11457.599 | U32: 11920.21 | V32: 11497.369 | W32: 11855.44 | X32: 12167.041 | Y32: 12269.628 | Z32: 11798.809 | AA32: 12125.937 | AB32: 12073.819 | AC32: 12216.79 | AD32: 10964.931 | AE32: 11392.284 | AF32: 11544.865 | AG32: 11292.646
A33: Entre Ríos | B33: vab | N33: 10433.914 | O33: 11702.555 | P33: 12454.632 | Q33: 13762.562 | R33: 14098.568 | S33: 13007.235 | T33: 14942.73 | U33: 15639.22 | V33: 15577.671 | W33: 16092.821 | X33: 15862.12 | Y33: 16422.062 | Z33: 15653.693 | AA33: 16435.788 | AB33: 15785.995 | AC33: 16031.456 | AD33: 14945.622 | AE33: 15947.948 | AF33: 16840.818 | AG33: 16133.861
A34: Formosa | B34: vab | N34: 2263.4085 | O34: 2557.0104 | P34: 2733.8165 | Q34: 2959.8669 | R34: 2946.203 | S34: 2943.6177 | T34: 3096.9127 | U34: 3368.9059 | V34: 3371.479 | W34: 3455.8572 | X34: 3413.8001 | Y34: 3616.8067 | Z34: 3602.6424 | AA34: 3694.748 | AB34: 3675.238 | AC34: 3463.4394 | AD34: 3211.2397 | AE34: 3594.987 | AF34: 3880.4603 | AG34: 3796.3607
A35: Jujuy | B35: vab | N35: 3654.7865 | O35: 3854.7524 | P35: 4095.1881 | Q35: 4428.6527 | R35: 4636.752 | S35: 4578.5937 | T35: 5056.4494 | U35: 5312.8809 | V35: 5440.9687 | W35: 5461.9901 | X35: 5507.3817 | Y35: 5765.1069 | Z35: 5554.7101 | AA35: 5722.259 | AB35: 5656.3562 | AC35: 5731.2107 | AD35: 5324.046 | AE35: 5996.4113 | AF35: 6600.8524 | AG35: 6832.0488
A36: La Pampa | B36: vab | N36: 3826.1282 | O36: 4607.3358 | P36: 4615.9539 | Q36: 5170.194 | R36: 5578.6797 | S36: 5164.537 | T36: 5514.9606 | U36: 5896.9155 | V36: 5900.3228 | W36: 5955.2736 | X36: 5675.1905 | Y36: 5982.8044 | Z36: 6190.1684 | AA36: 6008.986 | AB36: 5907.9746 | AC36: 6048.176 | AD36: 5434.2453 | AE36: 5867.0687 | AF36: 6427.5503 | AG36: 6122.8365
A37: La Rioja | B37: vab | N37: 2520.3505 | O37: 2718.3752 | P37: 2851.1011 | Q37: 3127.9344 | R37: 3082.2284 | S37: 2970.5202 | T37: 3280.8326 | U37: 3458.6401 | V37: 3331.5086 | W37: 3487.6157 | X37: 3364.3764 | Y37: 3439.1663 | Z37: 3389.2148 | AA37: 3499.0944 | AB37: 3374.5426 | AC37: 3290.8073 | AD37: 2906.7003 | AE37: 3212.7015 | AF37: 3474.285 | AG37: 3455.5029
... A73: Tucumán | B73: vab_indus | N73: 455.32839 | O73: 564.90301 | P73: 739.74755 | Q73: 832.58723 | R73: 755.00421 | S73: 581.17412 | T73: 1175.0619 | U73: 1904.6232 | V73: 2123.8669 | W73: 2108.9415 | X73: 1644.5431 | Y73: 1743.5015 | Z73: 1570.4401 | AA73: 1573.2059 | AB73: 1487.6486 | AC73: 1211.4287 | AD73: 1350.5913 | AE73: 1585.6123 | AF73: 1717.7105 | AG73: 1545.9171
A74: Buenos Aires | B74: expo | C74: =_xlfn.XLOOKUP($A74,'[1]Exportaciones Totales'!$A$8:$A$37,'[1]Exportaciones Totales'!B$8:B$37) -> 5198.553 | D74: =_xlfn.XLOOKUP($A74,'[1]Exportaciones Totales'!$A$8:$A$37,'[1]Exportaciones Totales'!C$8:C$37) -> 6223.191 | E74: =_xlfn.XLOOKUP($A74,'[1]Exportaciones Totales'!$A$8:$A$37,'[1]Exportaciones Totales'!D$8:D$37) -> 8133.711 | F74: =_xlfn.XLOOKUP($A74,'[1]Exportaciones Totales'!$A$8:$A$37,'[1]Exportaciones Totales'!E$8:E$37) -> 8908.843 | G74: =_xlfn.XLOOKUP($A74,'[1]Exportaciones Totales'!$A$8:$A$37,'[1]Exportaciones Totales'!F$8:F$37) -> 10367.901 | H74: =_xlfn.XLOOKUP($A74,'[1]Exportaciones Totales'!$A$8:$A$37,'[1]Exportaciones Totales'!G$8:G$37) -> 10427.197 | I74: =_xlfn.XLOOKUP($A74,'[1]Exportaciones Totales'!$A$8:$A$37,'[1]Exportaciones Totales'!H$8:H$37) -> 8572.211 | J74: =_xlfn.XLOOKUP($A74,'[1]Exportaciones Totales'!$A$8:$A$37,'[1]Exportaciones Totales'!I$8:I$37) -> 9640.077 | ... AH74: =_xlfn.XLOOKUP($A74,'[1]Exportaciones Totales'!$A$8:$A$37,'[1]Exportaciones Totales'!AG$8:AG$37) -> 29459.974 | AI74: 31683.845
A75: CABA | B75: expo | C75: =_xlfn.XLOOKUP($A75,'[1]Exportaciones Totales'!$A$8:$A$37,'[1]Exportaciones Totales'!B$8:B$37) -> 189.656 | D75: =_xlfn.XLOOKUP($A75,'[1]Exportaciones Totales'!$A$8:$A$37,'[1]Exportaciones Totales'!C$8:C$37) -> 306.914 | E75: =_xlfn.XLOOKUP($A75,'[1]Exportaciones Totales'!$A$8:$A$37,'[1]Exportaciones Totales'!D$8:D$37) -> 260.827 | F75: =_xlfn.XLOOKUP($A75,'[1]Exportaciones Totales'!$A$8:$A$37,'[1]Exportaciones Totales'!E$8:E$37) -> 255.946 | G75: =_xlfn.XLOOKUP($A75,'[1]Exportaciones Totales'!$A$8:$A$37,'[1]Exportaciones Totales'!F$8:F$37) -> 307.025 | H75: =_xlfn.XLOOKUP($A75,'[1]Exportaciones Totales'!$A$8:$A$37,'[1]Exportaciones Totales'!G$8:G$37) -> 287.199 | I75: =_xlfn.XLOOKUP($A75,'[1]Exportaciones Totales'!$A$8:$A$37,'[1]Exportaciones Totales'!H$8:H$37) -> 252.798 | J75: =_xlfn.XLOOKUP($A75,'[1]Exportaciones Totales'!$A$8:$A$37,'[1]Exportaciones Totales'!I$8:I$37) -> 235.949 | ... AH75: =_xlfn.XLOOKUP($A75,'[1]Exportaciones Totales'!$A$8:$A$37,'[1]Exportaciones Totales'!AG$8:AG$37) -> 363.70609 | AI75: 409.24717
A76: Catamarca | B76: expo | C76: =_xlfn.XLOOKUP($A76,'[1]Exportaciones Totales'!$A$8:$A$37,'[1]Exportaciones Totales'!B$8:B$37) -> 11.542 | D76: =_xlfn.XLOOKUP($A76,'[1]Exportaciones Totales'!$A$8:$A$37,'[1]Exportaciones Totales'!C$8:C$37) -> 25.035 | E76: =_xlfn.XLOOKUP($A76,'[1]Exportaciones Totales'!$A$8:$A$37,'[1]Exportaciones Totales'!D$8:D$37) -> 18.421 | F76: =_xlfn.XLOOKUP($A76,'[1]Exportaciones Totales'!$A$8:$A$37,'[1]Exportaciones Totales'!E$8:E$37) -> 21.61 | G76: =_xlfn.XLOOKUP($A76,'[1]Exportaciones Totales'!$A$8:$A$37,'[1]Exportaciones Totales'!F$8:F$37) -> 96.09 | H76: =_xlfn.XLOOKUP($A76,'[1]Exportaciones Totales'!$A$8:$A$37,'[1]Exportaciones Totales'!G$8:G$37) -> 490.266 | I76: =_xlfn.XLOOKUP($A76,'[1]Exportaciones Totales'!$A$8:$A$37,'[1]Exportaciones Totales'!H$8:H$37) -> 454.709 | J76: =_xlfn.XLOOKUP($A76,'[1]Exportaciones Totales'!$A$8:$A$37,'[1]Exportaciones Totales'!I$8:I$37) -> 337.45 | ... AH76: =_xlfn.XLOOKUP($A76,'[1]Exportaciones Totales'!$A$8:$A$37,'[1]Exportaciones Totales'!AG$8:AG$37) -> 340.70606 | AI76: 401.82761
A77: Chaco | B77: expo | C77: =_xlfn.XLOOKUP($A77,'[1]Exportaciones Totales'!$A$8:$A$37,'[1]Exportaciones Totales'!B$8:B$37) -> 152.621 | D77: =_xlfn.XLOOKUP($A77,'[1]Exportaciones Totales'!$A$8:$A$37,'[1]Exportaciones Totales'!C$8:C$37) -> 246.209 | E77: =_xlfn.XLOOKUP($A77,'[1]Exportaciones Totales'!$A$8:$A$37,'[1]Exportaciones Totales'!D$8:D$37) -> 389.407 | F77: =_xlfn.XLOOKUP($A77,'[1]Exportaciones Totales'!$A$8:$A$37,'[1]Exportaciones Totales'!E$8:E$37) -> 427.195 | G77: =_xlfn.XLOOKUP($A77,'[1]Exportaciones Totales'!$A$8:$A$37,'[1]Exportaciones Totales'!F$8:F$37) -> 321.314 | H77: =_xlfn.XLOOKUP($A77,'[1]Exportaciones Totales'!$A$8:$A$37,'[1]Exportaciones Totales'!G$8:G$37) -> 213.884 | I77: =_xlfn.XLOOKUP($A77,'[1]Exportaciones Totales'!$A$8:$A$37,'[1]Exportaciones Totales'!H$8:H$37) -> 216.209 | J77: =_xlfn.XLOOKUP($A77,'[1]Exportaciones Totales'!$A$8:$A$37,'[1]Exportaciones Totales'!I$8:I$37) -> 151.054 | ... AH77: =_xlfn.XLOOKUP($A77,'[1]Exportaciones Totales'!$A$8:$A$37,'[1]Exportaciones Totales'!AG$8:AG$37) -> 402.2464 | AI77: 234.96547
A78: Chubut | B78: expo | C78: =_xlfn.XLOOKUP($A78,'[1]Exportaciones Totales'!$A$8:$A$37,'[1]Exportaciones Totales'!B$8:B$37) -> 396.095 | D78: =_xlfn.XLOOKUP($A78,'[1]Exportaciones Totales'!$A$8:$A$37,'[1]Exportaciones Totales'!C$8:C$37) -> 540.394 | E78: =_xlfn.XLOOKUP($A78,'[1]Exportaciones Totales'!$A$8:$A$37,'[1]Exportaciones Totales'!D$8:D$37) -> 745.364 | F78: =_xlfn.XLOOKUP($A78,'[1]Exportaciones Totales'!$A$8:$A$37,'[1]Exportaciones Totales'!E$8:E$37) -> 841.906 | G78: =_xlfn.XLOOKUP($A78,'[1]Exportaciones Totales'!$A$8:$A$37,'[1]Exportaciones Totales'!F$8:F$37) -> 1064.383 | H78: =_xlfn.XLOOKUP($A78,'[1]Exportaciones Totales'!$A$8:$A$37,'[1]Exportaciones Totales'!G$8:G$37) -> 890.684 | I78: =_xlfn.XLOOKUP($A78,'[1]Exportaciones Totales'!$A$8:$A$37,'[1]Exportaciones Totales'!H$8:H$37) -> 878.023 | J78: =_xlfn.XLOOKUP($A78,'[1]Exportaciones Totales'!$A$8:$A$37,'[1]Exportaciones Totales'!I$8:I$37) -> 1286.261 | ... AH78: =_xlfn.XLOOKUP($A78,'[1]Exportaciones Totales'!$A$8:$A$37,'[1]Exportaciones Totales'!AG$8:AG$37) -> 3514.1678 | AI78: 3966.0485
A79: Córdoba | B79: expo | C79: =_xlfn.XLOOKUP($A79,'[1]Exportaciones Totales'!$A$8:$A$37,'[1]Exportaciones Totales'!B$8:B$37) -> 1398.998 | D79: =_xlfn.XLOOKUP($A79,'[1]Exportaciones Totales'!$A$8:$A$37,'[1]Exportaciones Totales'!C$8:C$37) -> 1599.301 | E79: =_xlfn.XLOOKUP($A79,'[1]Exportaciones Totales'!$A$8:$A$37,'[1]Exportaciones Totales'!D$8:D$37) -> 2000.343 | F79: =_xlfn.XLOOKUP($A79,'[1]Exportaciones Totales'!$A$8:$A$37,'[1]Exportaciones Totales'!E$8:E$37) -> 2332.419 | G79: =_xlfn.XLOOKUP($A79,'[1]Exportaciones Totales'!$A$8:$A$37,'[1]Exportaciones Totales'!F$8:F$37) -> 2718.829 | H79: =_xlfn.XLOOKUP($A79,'[1]Exportaciones Totales'!$A$8:$A$37,'[1]Exportaciones Totales'!G$8:G$37) -> 3098.446 | I79: =_xlfn.XLOOKUP($A79,'[1]Exportaciones Totales'!$A$8:$A$37,'[1]Exportaciones Totales'!H$8:H$37) -> 2550.369 | J79: =_xlfn.XLOOKUP($A79,'[1]Exportaciones Totales'!$A$8:$A$37,'[1]Exportaciones Totales'!I$8:I$37) -> 2770.218 | ... AH79: =_xlfn.XLOOKUP($A79,'[1]Exportaciones Totales'!$A$8:$A$37,'[1]Exportaciones Totales'!AG$8:AG$37) -> 9984.9516 | AI79: 10912.773
A80: Corrientes | B80: expo | C80: =_xlfn.XLOOKUP($A80,'[1]Exportaciones Totales'!$A$8:$A$37,'[1]Exportaciones Totales'!B$8:B$37) -> 65.877 | D80: =_xlfn.XLOOKUP($A80,'[1]Exportaciones Totales'!$A$8:$A$37,'[1]Exportaciones Totales'!C$8:C$37) -> 97.261 | E80: =_xlfn.XLOOKUP($A80,'[1]Exportaciones Totales'!$A$8:$A$37,'[1]Exportaciones Totales'!D$8:D$37) -> 144.953 | F80: =_xlfn.XLOOKUP($A80,'[1]Exportaciones Totales'!$A$8:$A$37,'[1]Exportaciones Totales'!E$8:E$37) -> 121.428 | G80: =_xlfn.XLOOKUP($A80,'[1]Exportaciones Totales'!$A$8:$A$37,'[1]Exportaciones Totales'!F$8:F$37) -> 128.699 | H80: =_xlfn.XLOOKUP($A80,'[1]Exportaciones Totales'!$A$8:$A$37,'[1]Exportaciones Totales'!G$8:G$37) -> 111.823 | I80: =_xlfn.XLOOKUP($A80,'[1]Exportaciones Totales'!$A$8:$A$37,'[1]Exportaciones Totales'!H$8:H$37) -> 117.637 | J80: =_xlfn.XLOOKUP($A80,'[1]Exportaciones Totales'!$A$8:$A$37,'[1]Exportaciones Totales'!I$8:I$37) -> 93.428 | ... AH80: =_xlfn.XLOOKUP($A80,'[1]Exportaciones Totales'!$A$8:$A$37,'[1]Exportaciones Totales'!AG$8:AG$37) -> 260.80262 | AI80: 335.57748
A81: Entre Ríos | B81: expo | C81: =_xlfn.XLOOKUP($A81,'[1]Exportaciones Totales'!$A$8:$A$37,'[1]Exportaciones Totales'!B$8:B$37) -> 222.322 | D81: =_xlfn.XLOOKUP($A81,'[1]Exportaciones Totales'!$A$8:$A$37,'[1]Exportaciones Totales'!C$8:C$37) -> 205.144 | E81: =_xlfn.XLOOKUP($A81,'[1]Exportaciones Totales'!$A$8:$A$37,'[1]Exportaciones Totales'!D$8:D$37) -> 381.723 | F81: =_xlfn.XLOOKUP($A81,'[1]Exportaciones Totales'!$A$8:$A$37,'[1]Exportaciones Totales'!E$8:E$37) -> 404.856 | G81: =_xlfn.XLOOKUP($A81,'[1]Exportaciones Totales'!$A$8:$A$37,'[1]Exportaciones Totales'!F$8:F$37) -> 479.773 | H81: =_xlfn.XLOOKUP($A81,'[1]Exportaciones Totales'!$A$8:$A$37,'[1]Exportaciones Totales'!G$8:G$37) -> 502.973 | I81: =_xlfn.XLOOKUP($A81,'[1]Exportaciones Totales'!$A$8:$A$37,'[1]Exportaciones Totales'!H$8:H$37) -> 331.451 | J81: =_xlfn.XLOOKUP($A81,'[1]Exportaciones Totales'!$A$8:$A$37,'[1]Exportaciones Totales'!I$8:I$37) -> 289.309 | ... AH81: =_xlfn.XLOOKUP($A81,'[1]Exportaciones Totales'!$A$8:$A$37,'[1]Exportaciones Totales'!AG$8:AG$37) -> 1426.9901 | AI81: 2115.2251
A82: Formosa | B82: expo | C82: =_xlfn.XLOOKUP($A82,'[1]Exportaciones Totales'!$A$8:$A$37,'[1]Exportaciones Totales'!B$8:B$37) -> 31.37 | D82: =_xlfn.XLOOKUP($A82,'[1]Exportaciones Totales'!$A$8:$A$37,'[1]Exportaciones Totales'!C$8:C$37) -> 35.035 | E82: =_xlfn.XLOOKUP($A82,'[1]Exportaciones Totales'!$A$8:$A$37,'[1]Exportaciones Totales'!D$8:D$37) -> 52.893 | F82: =_xlfn.XLOOKUP($A82,'[1]Exportaciones Totales'!$A$8:$A$37,'[1]Exportaciones Totales'!E$8:E$37) -> 56.168 | G82: =_xlfn.XLOOKUP($A82,'[1]Exportaciones Totales'!$A$8:$A$37,'[1]Exportaciones Totales'!F$8:F$37) -> 43.529 | H82: =_xlfn.XLOOKUP($A82,'[1]Exportaciones Totales'!$A$8:$A$37,'[1]Exportaciones Totales'!G$8:G$37) -> 29.837 | I82: =_xlfn.XLOOKUP($A82,'[1]Exportaciones Totales'!$A$8:$A$37,'[1]Exportaciones Totales'!H$8:H$37) -> 20.638 | J82: =_xlfn.XLOOKUP($A82,'[1]Exportaciones Totales'!$A$8:$A$37,'[1]Exportaciones Totales'!I$8:I$37) -> 14.164 | ... AH82: =_xlfn.XLOOKUP($A82,'[1]Exportaciones Totales'!$A$8:$A$37,'[1]Exportaciones Totales'!AG$8:AG$37) -> 37.09757 | AI82: 29.244629
A83: Jujuy | B83: expo | C83: =_xlfn.XLOOKUP($A83,'[1]Exportaciones Totales'!$A$8:$A$37,'[1]Exportaciones Totales'!B$8:B$37) -> 70.328 | D83: =_xlfn.XLOOKUP($A83,'[1]Exportaciones Totales'!$A$8:$A$37,'[1]Exportaciones Totales'!C$8:C$37) -> 70.706 | E83: =_xlfn.XLOOKUP($A83,'[1]Exportaciones Totales'!$A$8:$A$37,'[1]Exportaciones Totales'!D$8:D$37) -> 107.092 | F83: =_xlfn.XLOOKUP($A83,'[1]Exportaciones Totales'!$A$8:$A$37,'[1]Exportaciones Totales'!E$8:E$37) -> 148.578 | G83: =_xlfn.XLOOKUP($A83,'[1]Exportaciones Totales'!$A$8:$A$37,'[1]Exportaciones Totales'!F$8:F$37) -> 156.53 | H83: =_xlfn.XLOOKUP($A83,'[1]Exportaciones Totales'!$A$8:$A$37,'[1]Exportaciones Totales'!G$8:G$37) -> 119.857 | I83: =_xlfn.XLOOKUP($A83,'[1]Exportaciones Totales'!$A$8:$A$37,'[1]Exportaciones Totales'!H$8:H$37) -> 116.364 | J83: =_xlfn.XLOOKUP($A83,'[1]Exportaciones Totales'!$A$8:$A$37,'[1]Exportaciones Totales'!I$8:I$37) -> 95.038 | ... AH83: =_xlfn.XLOOKUP($A83,'[1]Exportaciones Totales'!$A$8:$A$37,'[1]Exportaciones Totales'!AG$8:AG$37) -> 1066.3066 | AI83: 1258.8057
A84: La Pampa | B84: expo | C84: =_xlfn.XLOOKUP($A84,'[1]Exportaciones Totales'!$A$8:$A$37,'[1]Exportaciones Totales'!B$8:B$37) -> 105.333 | D84: =_xlfn.XLOOKUP($A84,'[1]Exportaciones Totales'!$A$8:$A$37,'[1]Exportaciones Totales'!C$8:C$37) -> 130.924 | E84: =_xlfn.XLOOKUP($A84,'[1]Exportaciones Totales'!$A$8:$A$37,'[1]Exportaciones Totales'!D$8:D$37) -> 143.337 | F84: =_xlfn.XLOOKUP($A84,'[1]Exportaciones Totales'!$A$8:$A$37,'[1]Exportaciones Totales'!E$8:E$37) -> 145.741 | G84: =_xlfn.XLOOKUP($A84,'[1]Exportaciones Totales'!$A$8:$A$37,'[1]Exportaciones Totales'!F$8:F$37) -> 142.686 | H84: =_xlfn.XLOOKUP($A84,'[1]Exportaciones Totales'!$A$8:$A$37,'[1]Exportaciones Totales'!G$8:G$37) -> 210.022 | I84: =_xlfn.XLOOKUP($A84,'[1]Exportaciones Totales'!$A$8:$A$37,'[1]Exportaciones Totales'!H$8:H$37) -> 121.67 | J84: =_xlfn.XLOOKUP($A84,'[1]Exportaciones Totales'!$A$8:$A$37,'[1]Exportaciones Totales'!I$8:I$37) -> 124.502 | ... AH84: =_xlfn.XLOOKUP($A84,'[1]Exportaciones Totales'!$A$8:$A$37,'[1]Exportaciones Totales'!AG$8:AG$37) -> 1026.8637 | AI84: 938.96444
A85: La Rioja | B85: expo | C85: =_xlfn.XLOOKUP($A85,'[1]Exportaciones Totales'!$A$8:$A$37,'[1]Exportaciones Totales'!B$8:B$37) -> 46.612 | D85: =_xlfn.XLOOKUP($A85,'[1]Exportaciones Totales'!$A$8:$A$37,'[1]Exportaciones Totales'!C$8:C$37) -> 69.887 | E85: =_xlfn.XLOOKUP($A85,'[1]Exportaciones Totales'!$A$8:$A$37,'[1]Exportaciones Totales'!D$8:D$37) -> 136.023 | F85: =_xlfn.XLOOKUP($A85,'[1]Exportaciones Totales'!$A$8:$A$37,'[1]Exportaciones Totales'!E$8:E$37) -> 114.306 | G85: =_xlfn.XLOOKUP($A85,'[1]Exportaciones Totales'!$A$8:$A$37,'[1]Exportaciones Totales'!F$8:F$37) -> 145.647 | H85: =_xlfn.XLOOKUP($A85,'[1]Exportaciones Totales'!$A$8:$A$37,'[1]Exportaciones Totales'!G$8:G$37) -> 123.492 | I85: =_xlfn.XLOOKUP($A85,'[1]Exportaciones Totales'!$A$8:$A$37,'[1]Exportaciones Totales'!H$8:H$37) -> 117.947 | J85: =_xlfn.XLOOKUP($A85,'[1]Exportaciones Totales'!$A$8:$A$37,'[1]Exportaciones Totales'!I$8:I$37) -> 149.627 | ... AH85: =_xlfn.XLOOKUP($A85,'[1]Exportaciones Totales'!$A$8:$A$37,'[1]Exportaciones Totales'!AG$8:AG$37) -> 219.81355 | AI85: 163.35226
... A97: Tucumán | B97: expo | C97: =_xlfn.XLOOKUP($A97,'[1]Exportaciones Totales'!$A$8:$A$37,'[1]Exportaciones Totales'!B$8:B$37) -> 153.34 | D97: =_xlfn.XLOOKUP($A97,'[1]Exportaciones Totales'!$A$8:$A$37,'[1]Exportaciones Totales'!C$8:C$37) -> 223.73 | E97: =_xlfn.XLOOKUP($A97,'[1]Exportaciones Totales'!$A$8:$A$37,'[1]Exportaciones Totales'!D$8:D$37) -> 387.411 | F97: =_xlfn.XLOOKUP($A97,'[1]Exportaciones Totales'!$A$8:$A$37,'[1]Exportaciones Totales'!E$8:E$37) -> 362.48 | G97: =_xlfn.XLOOKUP($A97,'[1]Exportaciones Totales'!$A$8:$A$37,'[1]Exportaciones Totales'!F$8:F$37) -> 416.472 | H97: =_xlfn.XLOOKUP($A97,'[1]Exportaciones Totales'!$A$8:$A$37,'[1]Exportaciones Totales'!G$8:G$37) -> 383.302 | I97: =_xlfn.XLOOKUP($A97,'[1]Exportaciones Totales'!$A$8:$A$37,'[1]Exportaciones Totales'!H$8:H$37) -> 334.45 | J97: =_xlfn.XLOOKUP($A97,'[1]Exportaciones Totales'!$A$8:$A$37,'[1]Exportaciones Totales'!I$8:I$37) -> 407.764 | ... AH97: =_xlfn.XLOOKUP($A97,'[1]Exportaciones Totales'!$A$8:$A$37,'[1]Exportaciones Totales'!AG$8:AG$37) -> 955.65271 | AI97: 966.929
...

Sheet trim
A1: provincia | B1: variable | C1: I-96 | D1: II-96 | E1: III-96 | F1: IV-96 | G1: I-97 | H1: II-97 | I1: III-97 | J1: IV-97 | K1: I-98 | L1: II-98 | M1: III-98 | N1: IV-98 | O1: I-99 | P1: II-99 | Q1: III-99 | R1: IV-99 | S1: I-00 | T1: II-00 | U1: III-00 | V1: IV-00 | W1: I-01 | X1: II-01 | Y1: III-01 | Z1: IV-01 | AA1: I-02 | AB1: II-02 | AC1: III-02 | AD1: IV-02 | AE1: I-03 | AF1: II-03 | AG1: III-03 | AH1: IV-03 | AI1: I-04 | AJ1: II-04 | AK1: III-04 | AL1: IV-04 | AM1: I-05 | AN1: II-05 | AO1: III-05 | AP1: IV-05 | AQ1: I-06 | AR1: II-06 | AS1: III-06 | AT1: IV-06 | AU1: I-07 | AV1: II-07 | AW1: III-07 | AX1: IV-07 | AY1: I-08 | AZ1: II-08 | BA1: III-08 | BB1: IV-08 | BC1: I-09 | BD1: II-09 | BE1: III-09 | BF1: IV-09 | BG1: I-10 | BH1: II-10 | BI1: III-10 | BJ1: IV-10 | BK1: I-11 | BL1: II-11 | BM1: III-11 | BN1: IV-11 | BO1: I-12 | BP1: II-12 | BQ1: III-12 | BR1: IV-12 | BS1: I-13 | BT1: II-13 | BU1: III-13 | BV1: IV-13 | BW1: I-14 | BX1: II-14 | BY1: III-14 | BZ1: IV-14 | CA1: I-15 | CB1: II-15 | CC1: III-15 | CD1: IV-15 | CE1: I-16 | CF1: II-16 | CG1: III-16 | CH1: IV-16 | CI1: I-17 | CJ1: II-17 | CK1: III-17 | CL1: IV-17 | CM1: I-18 | CN1: II-18 | CO1: III-18 | CP1: IV-18 | CQ1: I-19 | CR1: II-19 | CS1: III-19 | CT1: IV-19 | CU1: I-20 | CV1: II-20 | CW1: III-20 | CX1: IV-20 | CY1: I-21 | CZ1: II-21 | DA1: III-21 | DB1: IV-21 | DC1: I-22 | DD1: II-22 | DE1: III-22 | DF1: IV-22 | DG1: I-23 | DH1: II-23 | DI1: III-23 | DJ1: IV-23 | DK1: I-24 | DL1: II-24 | DM1: III-24 | DN1: IV-24 | DO1: I-25 | DP1: II-25
A2: Buenos Aires | B2: empleo_indus | C2: 357520 | D2: 357526 | E2: 361794 | F2: 365827 | G2: 367217 | H2: 368433 | I2: 370351 | J2: 376750 | K2: 375488 | L2: 379729 | M2: 368590 | N2: 365318 | O2: 360321 | P2: 346593 | Q2: 341008 | R2: 366670 | S2: 348288 | T2: 340125 | U2: 339106 | V2: 340871 | W2: 338276 | X2: 329101 | Y2: 323373 | Z2: 313351 | AA2: 297650 | AB2: 290217 | AC2: 289539 | AD2: 294253 | AE2: 299526 | AF2: 305768 | AG2: 317367 | AH2: 330093 | AI2: 340317 | AJ2: 346199 | AK2: 358737 | AL2: 373425 | AM2: 381107 | AN2: 388940 | AO2: 398055 | AP2: 411062 | AQ2: 417056 | AR2: 422984 | AS2: 433142 | AT2: 442875 | AU2: 451670 | AV2: 455806 | AW2: 466128 | AX2: 478321 | AY2: 487625 | AZ2: 492279 | BA2: 497372 | BB2: 498135 | BC2: 488182 | BD2: 481285 | BE2: 481696 | BF2: 488730 | BG2: 492444 | BH2: 493167 | BI2: 497976 | BJ2: 504632 | BK2: 509403 | BL2: 511600 | BM2: 518641 | BN2: 525896 | BO2: 527691 | BP2: 525791 | BQ2: 526951 | BR2: 533310 | BS2: 535955 | BT2: 533393 | BU2: 535235 | BV2: 539632 | BW2: 536634 | BX2: 531468 | BY2: 528450 | BZ2: 531518 | CA2: 532232 | CB2: 534411 | CC2: 538119 | CD2: 539226 | CE2: 537861 | CF2: 530141 | CG2: 526481 | CH2: 526988 | CI2: 526121 | CJ2: 522486 | CK2: 520760 | CL2: 522125 | CM2: 521584 | CN2: 513676 | CO2: 504938 | CP2: 498411 | CQ2: 494968 | CR2: 486137 | CS2: 481831 | CT2: 480685 | CU2: 479340 | CV2: 473319 | CW2: 478218 | CX2: 482736 | CY2: 491387 | CZ2: 494630 | DA2: 497862 | DB2: 504344 | DC2: 516442 | DD2: 522537 | DE2: 527731 | DF2: 531879 | DG2: 539967 | DH2: 540053 | DI2: 542798 | DJ2: 542178 | DK2: 539273 | DL2: 528737 | DM2: 524628 | DN2: 526819 | DO2: 526473 | DP2: 521976
A3: CABA | B3: empleo_indus | C3: 181119 | D3: 184594 | E3: 184131 | F3: 187230 | G3: 187428 | H3: 190681 | I3: 191369 | J3: 193323 | K3: 193022 | L3: 201122 | M3: 196745 | N3: 194780 | O3: 194574 | P3: 192775 | Q3: 189998 | R3: 193546 | S3: 168789 | T3: 166024 | U3: 164277 | V3: 162578 | W3: 162367 | X3: 160378 | Y3: 156607 | Z3: 149228 | AA3: 140398 | AB3: 135970 | AC3: 134050 | AD3: 136253 | AE3: 137607 | AF3: 139864 | AG3: 146127 | AH3: 152042 | AI3: 155826 | AJ3: 159509 | AK3: 164809 | AL3: 169442 | AM3: 172253 | AN3: 176675 | AO3: 180343 | AP3: 185342 | AQ3: 187450 | AR3: 192248 | AS3: 195639 | AT3: 201670 | AU3: 203473 | AV3: 205920 | AW3: 210735 | AX3: 214745 | AY3: 214437 | AZ3: 217344 | BA3: 219630 | BB3: 219879 | BC3: 216521 | BD3: 213305 | BE3: 211786 | BF3: 212577 | BG3: 211874 | BH3: 214296 | BI3: 215959 | BJ3: 217536 | BK3: 216369 | BL3: 217342 | BM3: 218715 | BN3: 221012 | BO3: 218085 | BP3: 216445 | BQ3: 214768 | BR3: 214891 | BS3: 212990 | BT3: 212777 | BU3: 212925 | BV3: 213486 | BW3: 212924 | BX3: 210630 | BY3: 210239 | BZ3: 210806 | CA3: 211764 | CB3: 214009 | CC3: 214421 | CD3: 215034 | CE3: 213066 | CF3: 210583 | CG3: 207643 | CH3: 206473 | CI3: 203600 | CJ3: 201749 | CK3: 200856 | CL3: 200662 | CM3: 198677 | CN3: 194160 | CO3: 190405 | CP3: 186396 | CQ3: 183994 | CR3: 181081 | CS3: 178801 | CT3: 177611 | CU3: 174299 | CV3: 170561 | CW3: 170690 | CX3: 170987 | CY3: 170676 | CZ3: 169945 | DA3: 169899 | DB3: 172273 | DC3: 173186 | DD3: 176193 | DE3: 177024 | DF3: 177702 | DG3: 178690 | DH3: 180061 | DI3: 182596 | DJ3: 182890 | DK3: 179012 | DL3: 176133 | DM3: 176982 | DN3: 177161 | DO3: 176045 | DP3: 175596
A4: Catamarca | B4: empleo_indus | C4: 4993 | D4: 4776 | E4: 4856 | F4: 5457 | G4: 6139 | H4: 5869 | I4: 5709 | J4: 6333 | K4: 6406 | L4: 6976 | M4: 6884 | N4: 7160 | O4: 7151 | P4: 7625 | Q4: 7606 | R4: 8371 | S4: 6251 | T4: 6172 | U4: 5951 | V4: 6098 | W4: 5660 | X4: 5651 | Y4: 5615 | Z4: 5531 | AA4: 5049 | AB4: 4879 | AC4: 4965 | AD4: 5065 | AE4: 5140 | AF4: 5159 | AG4: 5133 | AH4: 5273 | AI4: 5762 | AJ4: 5952 | AK4: 5926 | AL4: 5987 | AM4: 6054 | AN4: 6264 | AO4: 6252 | AP4: 6435 | AQ4: 6454 | AR4: 6492 | AS4: 6437 | AT4: 6369 | AU4: 6301 | AV4: 6406 | AW4: 6304 | AX4: 6293 | AY4: 6294 | AZ4: 6375 | BA4: 6158 | BB4: 6009 | BC4: 5966 | BD4: 5854 | BE4: 5919 | BF4: 6010 | BG4: 6102 | BH4: 6325 | BI4: 6500 | BJ4: 6257 | BK4: 6485 | BL4: 6473 | BM4: 6564 | BN4: 6436 | BO4: 6376 | BP4: 6401 | BQ4: 6270 | BR4: 6501 | BS4: 6203 | BT4: 6313 | BU4: 6352 | BV4: 6512 | BW4: 6426 | BX4: 7013 | BY4: 6959 | BZ4: 6957 | CA4: 6824 | CB4: 6735 | CC4: 6542 | CD4: 6477 | CE4: 6234 | CF4: 6159 | CG4: 6091 | CH4: 6053 | CI4: 6273 | CJ4: 6336 | CK4: 6131 | CL4: 5959 | CM4: 5817 | CN4: 5637 | CO4: 5511 | CP4: 5440 | CQ4: 5273 | CR4: 5157 | CS4: 4778 | CT4: 4724 | CU4: 4865 | CV4: 4655 | CW4: 4697 | CX4: 4843 | CY4: 5076 | CZ4: 5326 | DA4: 5207 | DB4: 5456 | DC4: 5667 | DD4: 5786 | DE4: 6030 | DF4: 6128 | DG4: 6211 | DH4: 6452 | DI4: 6629 | DJ4: 6635 | DK4: 6371 | DL4: 6140 | DM4: 6423 | DN4: 6525 | DO4: 6574 | DP4: 6553
A5: Chaco | B5: empleo_indus | C5: 6519 | D5: 7918 | E5: 8068 | F5: 6831 | G5: 7101 | H5: 8344 | I5: 7377 | J5: 6689 | K5: 6609 | L5: 7360 | M5: 7360 | N5: 6333 | O5: 5990 | P5: 6444 | Q5: 5711 | R5: 5392 | S5: 5570 | T5: 6228 | U5: 6063 | V5: 5634 | W5: 5736 | X5: 6178 | Y5: 5604 | Z5: 4929 | AA5: 4664 | AB5: 5050 | AC5: 4811 | AD5: 4650 | AE5: 4834 | AF5: 5183 | AG5: 5050 | AH5: 5038 | AI5: 5388 | AJ5: 5725 | AK5: 5561 | AL5: 5625 | AM5: 5815 | AN5: 6053 | AO5: 5742 | AP5: 5685 | AQ5: 5820 | AR5: 6458 | AS5: 6518 | AT5: 6130 | AU5: 6374 | AV5: 6859 | AW5: 6677 | AX5: 6486 | AY5: 6744 | AZ5: 7448 | BA5: 7161 | BB5: 7052 | BC5: 7064 | BD5: 7881 | BE5: 7873 | BF5: 7708 | BG5: 7279 | BH5: 7791 | BI5: 7925 | BJ5: 7462 | BK5: 7301 | BL5: 7940 | BM5: 8235 | BN5: 8094 | BO5: 7841 | BP5: 8132 | BQ5: 7931 | BR5: 7794 | BS5: 7837 | BT5: 8108 | BU5: 8072 | BV5: 7863 | BW5: 7796 | BX5: 8212 | BY5: 8357 | BZ5: 8143 | CA5: 8070 | CB5: 8321 | CC5: 8347 | CD5: 7995 | CE5: 7955 | CF5: 8358 | CG5: 8329 | CH5: 7871 | CI5: 7870 | CJ5: 7951 | CK5: 8038 | CL5: 7993 | CM5: 7968 | CN5: 8145 | CO5: 8028 | CP5: 7885 | CQ5: 7815 | CR5: 7846 | CS5: 7859 | CT5: 7612 | CU5: 7450 | CV5: 7476 | CW5: 7545 | CX5: 7310 | CY5: 7326 | CZ5: 7600 | DA5: 7310 | DB5: 7127 | DC5: 7187 | DD5: 7448 | DE5: 7573 | DF5: 7485 | DG5: 7598 | DH5: 8053 | DI5: 7985 | DJ5: 7599 | DK5: 7397 | DL5: 7522 | DM5: 7480 | DN5: 7203 | DO5: 7179 | DP5: 7304
A6: Chubut | B6: empleo_indus | C6: 7546 | D6: 6731 | E6: 6477 | F6: 6424 | G6: 6818 | H6: 6531 | I6: 6621 | J6: 7155 | K6: 7792 | L6: 8715 | M6: 8239 | N6: 8217 | O6: 8451 | P6: 8014 | Q6: 7523 | R6: 8273 | S6: 8240 | T6: 8114 | U6: 7954 | V6: 8182 | W6: 8196 | X6: 8217 | Y6: 8036 | Z6: 7790 | AA6: 7743 | AB6: 7695 | AC6: 7591 | AD6: 8119 | AE6: 8697 | AF6: 8752 | AG6: 9172 | AH6: 9598 | AI6: 10120 | AJ6: 10196 | AK6: 10117 | AL6: 10454 | AM6: 10840 | AN6: 10599 | AO6: 10435 | AP6: 11197 | AQ6: 11862 | AR6: 11755 | AS6: 12112 | AT6: 12264 | AU6: 12527 | AV6: 12492 | AW6: 12620 | AX6: 12797 | AY6: 13280 | AZ6: 13086 | BA6: 12893 | BB6: 12843 | BC6: 12770 | BD6: 12083 | BE6: 11742 | BF6: 11623 | BG6: 11803 | BH6: 11765 | BI6: 11885 | BJ6: 11889 | BK6: 12119 | BL6: 12186 | BM6: 12255 | BN6: 12438 | BO6: 12379 | BP6: 11912 | BQ6: 12342 | BR6: 12562 | BS6: 12494 | BT6: 12104 | BU6: 12326 | BV6: 12712 | BW6: 12864 | BX6: 12837 | BY6: 13261 | BZ6: 13673 | CA6: 13605 | CB6: 13011 | CC6: 13227 | CD6: 13293 | CE6: 13688 | CF6: 13054 | CG6: 13188 | CH6: 13169 | CI6: 13563 | CJ6: 12565 | CK6: 12940 | CL6: 12791 | CM6: 13187 | CN6: 12422 | CO6: 13430 | CP6: 13080 | CQ6: 13641 | CR6: 12539 | CS6: 13768 | CT6: 13254 | CU6: 14015 | CV6: 12232 | CW6: 13200 | CX6: 13726 | CY6: 13971 | CZ6: 12865 | DA6: 13923 | DB6: 13406 | DC6: 14300 | DD6: 12939 | DE6: 13823 | DF6: 13431 | DG6: 14402 | DH6: 13052 | DI6: 14122 | DJ6: 13728 | DK6: 15280 | DL6: 13653 | DM6: 14533 | DN6: 14802 | DO6: 15538 | DP6: 12584
A7: Córdoba | B7: empleo_indus | C7: 67161 | D7: 69086 | E7: 71192 | F7: 73171 | G7: 73578 | H7: 76509 | I7: 79289 | J7: 80876 | K7: 79847 | L7: 82026 | M7: 81550 | N7: 79779 | O7: 76292 | P7: 73843 | Q7: 72090 | R7: 73765 | S7: 70559 | T7: 70446 | U7: 69038 | V7: 68730 | W7: 67544 | X7: 66815 | Y7: 64948 | Z7: 63061 | AA7: 58313 | AB7: 57521 | AC7: 56645 | AD7: 57397 | AE7: 58447 | AF7: 60047 | AG7: 62272 | AH7: 64982 | AI7: 66197 | AJ7: 68727 | AK7: 70726 | AL7: 73310 | AM7: 74332 | AN7: 76835 | AO7: 78721 | AP7: 81633 | AQ7: 83018 | AR7: 83843 | AS7: 85410 | AT7: 87648 | AU7: 88245 | AV7: 89943 | AW7: 92540 | AX7: 95672 | AY7: 97636 | AZ7: 99842 | BA7: 100725 | BB7: 100701 | BC7: 97197 | BD7: 95574 | BE7: 96344 | BF7: 98039 | BG7: 98430 | BH7: 99630 | BI7: 101419 | BJ7: 103023 | BK7: 104359 | BL7: 106641 | BM7: 108190 | BN7: 109613 | BO7: 109054 | BP7: 108511 | BQ7: 109136 | BR7: 110116 | BS7: 110669 | BT7: 110975 | BU7: 112318 | BV7: 112472 | BW7: 112292 | BX7: 110340 | BY7: 109720 | BZ7: 109459 | CA7: 110178 | CB7: 110403 | CC7: 110915 | CD7: 110728 | CE7: 110846 | CF7: 109519 | CG7: 109038 | CH7: 107974 | CI7: 108749 | CJ7: 108605 | CK7: 109182 | CL7: 110015 | CM7: 110219 | CN7: 109580 | CO7: 108221 | CP7: 106635 | CQ7: 105122 | CR7: 103855 | CS7: 102936 | CT7: 101871 | CU7: 100554 | CV7: 99885 | CW7: 100967 | CX7: 102516 | CY7: 104446 | CZ7: 106090 | DA7: 106822 | DB7: 109157 | DC7: 109306 | DD7: 111751 | DE7: 113479 | DF7: 114232 | DG7: 115722 | DH7: 117331 | DI7: 117966 | DJ7: 116968 | DK7: 114967 | DL7: 113409 | DM7: 113105 | DN7: 113441 | DO7: 114552 | DP7: 114453
A8: Corrientes | B8: empleo_indus | C8: 7392 | D8: 7194 | E8: 7210 | F8: 7484 | G8: 7668 | H8: 7756 | I8: 7741 | J8: 7662 | K8: 7420 | L8: 7720 | M8: 8336 | N8: 7609 | O8: 7619 | P8: 6395 | Q8: 6247 | R8: 7676 | S8: 7566 | T8: 7293 | U8: 7001 | V8: 6953 | W8: 7317 | X8: 7443 | Y8: 7955 | Z8: 6738 | AA8: 7211 | AB8: 6770 | AC8: 7186 | AD8: 7268 | AE8: 7232 | AF8: 7713 | AG8: 7771 | AH8: 7782 | AI8: 7772 | AJ8: 8245 | AK8: 8445 | AL8: 8571 | AM8: 8781 | AN8: 9310 | AO8: 9468 | AP8: 9235 | AQ8: 9319 | AR8: 9994 | AS8: 10572 | AT8: 10019 | AU8: 9963 | AV8: 10476 | AW8: 10707 | AX8: 10513 | AY8: 10720 | AZ8: 11070 | BA8: 11096 | BB8: 11214 | BC8: 10919 | BD8: 11120 | BE8: 11238 | BF8: 11300 | BG8: 11286 | BH8: 11530 | BI8: 11181 | BJ8: 11281 | BK8: 11164 | BL8: 11400 | BM8: 11409 | BN8: 11694 | BO8: 11585 | BP8: 11325 | BQ8: 11434 | BR8: 11593 | BS8: 11410 | BT8: 11566 | BU8: 11570 | BV8: 11833 | BW8: 11557 | BX8: 12121 | BY8: 12332 | BZ8: 12401 | CA8: 12315 | CB8: 12304 | CC8: 12537 | CD8: 12679 | CE8: 12350 | CF8: 11802 | CG8: 12287 | CH8: 12488 | CI8: 12088 | CJ8: 12178 | CK8: 12512 | CL8: 12367 | CM8: 12253 | CN8: 12291 | CO8: 12265 | CP8: 12527 | CQ8: 12316 | CR8: 12373 | CS8: 12653 | CT8: 12702 | CU8: 11928 | CV8: 11758 | CW8: 12262 | CX8: 12583 | CY8: 12494 | CZ8: 12810 | DA8: 13243 | DB8: 13249 | DC8: 13220 | DD8: 13329 | DE8: 14096 | DF8: 13925 | DG8: 13830 | DH8: 13663 | DI8: 13820 | DJ8: 13631 | DK8: 13533 | DL8: 13302 | DM8: 13525 | DN8: 13555 | DO8: 13447 | DP8: 13218
A9: Entre Ríos | B9: empleo_indus | C9: 17222 | D9: 17322 | E9: 16678 | F9: 17008 | G9: 17120 | H9: 17044 | I9: 17010 | J9: 17746 | K9: 17393 | L9: 17025 | M9: 16578 | N9: 16984 | O9: 16900 | P9: 16376 | Q9: 15583 | R9: 16091 | S9: 15747 | T9: 15493 | U9: 15308 | V9: 14782 | W9: 14869 | X9: 14898 | Y9: 14675 | Z9: 14223 | AA9: 13442 | AB9: 13098 | AC9: 13111 | AD9: 13280 | AE9: 13612 | AF9: 13915 | AG9: 14610 | AH9: 15402 | AI9: 15862 | AJ9: 16238 | AK9: 16479 | AL9: 17413 | AM9: 18012 | AN9: 18115 | AO9: 18501 | AP9: 19394 | AQ9: 19831 | AR9: 20081 | AS9: 20634 | AT9: 21717 | AU9: 22160 | AV9: 22264 | AW9: 22777 | AX9: 23681 | AY9: 23947 | AZ9: 23902 | BA9: 24206 | BB9: 24332 | BC9: 24607 | BD9: 24312 | BE9: 25075 | BF9: 25044 | BG9: 25101 | BH9: 25048 | BI9: 25261 | BJ9: 25420 | BK9: 25936 | BL9: 26113 | BM9: 26498 | BN9: 27507 | BO9: 27627 | BP9: 27493 | BQ9: 27712 | BR9: 28228 | BS9: 28370 | BT9: 28140 | BU9: 28150 | BV9: 28367 | BW9: 28384 | BX9: 28228 | BY9: 28384 | BZ9: 28655 | CA9: 28827 | CB9: 29118 | CC9: 29143 | CD9: 29178 | CE9: 29421 | CF9: 28971 | CG9: 28911 | CH9: 28995 | CI9: 28959 | CJ9: 28967 | CK9: 28564 | CL9: 28781 | CM9: 28936 | CN9: 28948 | CO9: 28846 | CP9: 28778 | CQ9: 28565 | CR9: 28705 | CS9: 28576 | CT9: 28277 | CU9: 28357 | CV9: 28013 | CW9: 28445 | CX9: 28962 | CY9: 29463 | CZ9: 29503 | DA9: 29799 | DB9: 30196 | DC9: 30600 | DD9: 30755 | DE9: 31227 | DF9: 31573 | DG9: 31706 | DH9: 31705 | DI9: 31698 | DJ9: 31676 | DK9: 31633 | DL9: 31089 | DM9: 30860 | DN9: 31038 | DO9: 30989 | DP9: 30840
A10: Formosa | B10: empleo_indus | C10: 1463 | D10: 1585 | E10: 1572 | F10: 1518 | G10: 1587 | H10: 1616 | I10: 1629 | J10: 1567 | K10: 1572 | L10: 1654 | M10: 1688 | N10: 1656 | O10: 1422 | P10: 1430 | Q10: 1435 | R10: 1436 | S10: 1378 | T10: 1326 | U10: 1334 | V10: 1255 | W10: 1283 | X10: 1276 | Y10: 1245 | Z10: 1149 | AA10: 1089 | AB10: 1067 | AC10: 1064 | AD10: 1031 | AE10: 976 | AF10: 1036 | AG10: 1066 | AH10: 1160 | AI10: 1178 | AJ10: 1236 | AK10: 1274 | AL10: 1359 | AM10: 1269 | AN10: 1316 | AO10: 1327 | AP10: 1513 | AQ10: 1499 | AR10: 1562 | AS10: 1392 | AT10: 1476 | AU10: 1516 | AV10: 1561 | AW10: 1617 | AX10: 1582 | AY10: 1617 | AZ10: 1653 | BA10: 1621 | BB10: 1649 | BC10: 1653 | BD10: 1707 | BE10: 1713 | BF10: 1668 | BG10: 1608 | BH10: 1625 | BI10: 1595 | BJ10: 1622 | BK10: 1739 | BL10: 1734 | BM10: 1721 | BN10: 1745 | BO10: 1699 | BP10: 1726 | BQ10: 1837 | BR10: 1826 | BS10: 1711 | BT10: 1718 | BU10: 1696 | BV10: 1652 | BW10: 1673 | BX10: 1683 | BY10: 1691 | BZ10: 1681 | CA10: 1715 | CB10: 1723 | CC10: 1743 | CD10: 1792 | CE10: 1773 | CF10: 1869 | CG10: 1823 | CH10: 1796 | CI10: 1830 | CJ10: 1836 | CK10: 1810 | CL10: 1810 | CM10: 1797 | CN10: 1758 | CO10: 1714 | CP10: 1702 | CQ10: 1670 | CR10: 1643 | CS10: 1630 | CT10: 1613 | CU10: 1653 | CV10: 1677 | CW10: 1653 | CX10: 1720 | CY10: 1791 | CZ10: 1748 | DA10: 1602 | DB10: 1621 | DC10: 1716 | DD10: 1786 | DE10: 1851 | DF10: 1834 | DG10: 1785 | DH10: 1720 | DI10: 1744 | DJ10: 1703 | DK10: 1698 | DL10: 1666 | DM10: 1639 | DN10: 1681 | DO10: 1677 | DP10: 1695
A11: Jujuy | B11: empleo_indus | C11: 9125 | D11: 9251 | E11: 9467 | F11: 10684 | G11: 9809 | H11: 10281 | I11: 9382 | J11: 9057 | K11: 8423 | L11: 9053 | M11: 9208 | N11: 8385 | O11: 7531 | P11: 8033 | Q11: 8825 | R11: 10128 | S11: 7797 | T11: 8584 | U11: 10742 | V11: 8819 | W11: 7526 | X11: 8843 | Y11: 10754 | Z11: 8765 | AA11: 6926 | AB11: 8245 | AC11: 9850 | AD11: 8278 | AE11: 8666 | AF11: 9653 | AG11: 11257 | AH11: 10008 | AI11: 9673 | AJ11: 10429 | AK11: 11919 | AL11: 10475 | AM11: 10133 | AN11: 10884 | AO11: 12027 | AP11: 10449 | AQ11: 9455 | AR11: 10654 | AS11: 12037 | AT11: 10735 | AU11: 9527 | AV11: 10906 | AW11: 12261 | AX11: 11018 | AY11: 9849 | AZ11: 11471 | BA11: 12387 | BB11: 11108 | BC11: 10336 | BD11: 11845 | BE11: 13217 | BF11: 12126 | BG11: 10499 | BH11: 12173 | BI11: 12558 | BJ11: 12505 | BK11: 12679 | BL11: 13312 | BM11: 13312 | BN11: 13232 | BO11: 12547 | BP11: 12717 | BQ11: 12722 | BR11: 12735 | BS11: 12106 | BT11: 12480 | BU11: 12324 | BV11: 12345 | BW11: 11574 | BX11: 12127 | BY11: 12624 | BZ11: 12670 | CA11: 12430 | CB11: 12844 | CC11: 12631 | CD11: 12414 | CE11: 12201 | CF11: 12362 | CG11: 12404 | CH11: 12360 | CI11: 12138 | CJ11: 12638 | CK11: 12634 | CL11: 12355 | CM11: 11949 | CN11: 12146 | CO11: 11922 | CP11: 11960 | CQ11: 11462 | CR11: 11390 | CS11: 11028 | CT11: 11149 | CU11: 11436 | CV11: 12120 | CW11: 12147 | CX11: 11685 | CY11: 11432 | CZ11: 11852 | DA11: 11814 | DB11: 11597 | DC11: 11778 | DD11: 11967 | DE11: 11851 | DF11: 11690 | DG11: 11606 | DH11: 11558 | DI11: 11467 | DJ11: 11238 | DK11: 11288 | DL11: 11357 | DM11: 11344 | DN11: 11154 | DO11: 11266 | DP11: 10891
A12: La Pampa | B12: empleo_indus | C12: 2430 | D12: 2486 | E12: 2496 | F12: 2506 | G12: 2511 | H12: 2631 | I12: 2614 | J12: 2978 | K12: 2952 | L12: 3070 | M12: 2990 | N12: 2902 | O12: 2967 | P12: 2666 | Q12: 2659 | R12: 2577 | S12: 2370 | T12: 2295 | U12: 2257 | V12: 2192 | W12: 2221 | X12: 2192 | Y12: 2221 | Z12: 2148 | AA12: 2085 | AB12: 2084 | AC12: 2150 | AD12: 2222 | AE12: 2342 | AF12: 2372 | AG12: 2454 | AH12: 2590 | AI12: 2822 | AJ12: 2654 | AK12: 2723 | AL12: 2855 | AM12: 2928 | AN12: 3039 | AO12: 3137 | AP12: 3163 | AQ12: 3262 | AR12: 3253 | AS12: 3248 | AT12: 3322 | AU12: 3417 | AV12: 3431 | AW12: 3598 | AX12: 3624 | AY12: 3759 | AZ12: 3905 | BA12: 3926 | BB12: 4025 | BC12: 4054 | BD12: 4086 | BE12: 4037 | BF12: 4058 | BG12: 4031 | BH12: 3954 | BI12: 3843 | BJ12: 3896 | BK12: 3969 | BL12: 3848 | BM12: 3907 | BN12: 3886 | BO12: 3840 | BP12: 4333 | BQ12: 4180 | BR12: 4191 | BS12: 4236 | BT12: 4267 | BU12: 4287 | BV12: 4180 | BW12: 4127 | BX12: 4220 | BY12: 4317 | BZ12: 4373 | CA12: 4456 | CB12: 4575 | CC12: 4636 | CD12: 4713 | CE12: 4830 | CF12: 4870 | CG12: 4967 | CH12: 4863 | CI12: 4923 | CJ12: 4840 | CK12: 4407 | CL12: 4437 | CM12: 4530 | CN12: 4674 | CO12: 4609 | CP12: 4339 | CQ12: 4416 | CR12: 4427 | CS12: 4476 | CT12: 4487 | CU12: 4384 | CV12: 4264 | CW12: 4404 | CX12: 4474 | CY12: 4592 | CZ12: 4689 | DA12: 4815 | DB12: 4779 | DC12: 4974 | DD12: 5175 | DE12: 5523 | DF12: 5330 | DG12: 5381 | DH12: 5380 | DI12: 5556 | DJ12: 5568 | DK12: 5678 | DL12: 5468 | DM12: 5494 | DN12: 5480 | DO12: 5291 | DP12: 5125
A13: La Rioja | B13: empleo_indus | C13: 6566 | D13: 6614 | E13: 6591 | F13: 6774 | G13: 7432 | H13: 7532 | I13: 7750 | J13: 7742 | K13: 8193 | L13: 8352 | M13: 8213 | N13: 7898 | O13: 8016 | P13: 7812 | Q13: 7912 | R13: 8236 | S13: 8080 | T13: 7941 | U13: 7846 | V13: 7907 | W13: 8003 | X13: 7885 | Y13: 7855 | Z13: 7581 | AA13: 7414 | AB13: 7335 | AC13: 7431 | AD13: 7631 | AE13: 7975 | AF13: 8066 | AG13: 8076 | AH13: 8375 | AI13: 6341 | AJ13: 6309 | AK13: 6366 | AL13: 6505 | AM13: 6929 | AN13: 7331 | AO13: 7165 | AP13: 7221 | AQ13: 7435 | AR13: 7662 | AS13: 7424 | AT13: 7597 | AU13: 8161 | AV13: 7997 | AW13: 7790 | AX13: 7850 | AY13: 8099 | AZ13: 7919 | BA13: 7685 | BB13: 7425 | BC13: 7855 | BD13: 6860 | BE13: 6906 | BF13: 6967 | BG13: 9544 | BH13: 9430 | BI13: 8915 | BJ13: 9531 | BK13: 10485 | BL13: 10976 | BM13: 9621 | BN13: 9749 | BO13: 10406 | BP13: 9987 | BQ13: 9568 | BR13: 9728 | BS13: 9353 | BT13: 9131 | BU13: 8015 | BV13: 7968 | BW13: 8893 | BX13: 8347 | BY13: 7700 | BZ13: 7509 | CA13: 9527 | CB13: 9647 | CC13: 8256 | CD13: 8003 | CE13: 9521 | CF13: 8854 | CG13: 7960 | CH13: 7746 | CI13: 8861 | CJ13: 8444 | CK13: 7242 | CL13: 7207 | CM13: 7400 | CN13: 7046 | CO13: 6472 | CP13: 6268 | CQ13: 7383 | CR13: 7273 | CS13: 6533 | CT13: 6415 | CU13: 6967 | CV13: 6695 | CW13: 6010 | CX13: 5943 | CY13: 6897 | CZ13: 6798 | DA13: 6341 | DB13: 6430 | DC13: 8212 | DD13: 8645 | DE13: 8262 | DF13: 8425 | DG13: 9039 | DH13: 9545 | DI13: 8894 | DJ13: 8775 | DK13: 9155 | DL13: 8991 | DM13: 8326 | DN13: 8272 | DO13: 8763 | DP13: 8454
... A49: Tucumán | B49: empleo | C49: 70722 | D49: 76515 | E49: 85439 | F49: 81647 | G49: 77533 | H49: 87906 | I49: 93715 | J49: 86231 | K49: 81429 | L49: 89594 | M49: 94230 | N49: 89583 | O49: 80400 | P49: 86090 | Q49: 93817 | R49: 95488 | S49: 83741 | T49: 92017 | U49: 99542 | V49: 91159 | W49: 85379 | X49: 97052 | Y49: 103323 | Z49: 88769 | AA49: 78922 | AB49: 91017 | AC49: 95385 | AD49: 80973 | AE49: 80727 | AF49: 98153 | AG49: 103622 | AH49: 88451 | AI49: 88251 | AJ49: 109941 | AK49: 114511 | AL49: 100850 | AM49: 99384 | AN49: 123808 | AO49: 128683 | AP49: 113271 | AQ49: 107701 | AR49: 129863 | AS49: 136765 | AT49: 124834 | AU49: 117718 | AV49: 141571 | AW49: 150097 | AX49: 149540 | AY49: 142820 | AZ49: 172617 | BA49: 170668 | BB49: 158408 | BC49: 141264 | BD49: 163988 | BE49: 168349 | BF49: 156834 | BG49: 140590 | BH49: 162669 | BI49: 167415 | BJ49: 156833 | BK49: 148354 | BL49: 171064 | BM49: 173950 | BN49: 169211 | BO49: 158524 | BP49: 174972 | BQ49: 177256 | BR49: 165426 | BS49: 159085 | BT49: 175267 | BU49: 174860 | BV49: 161126 | BW49: 153623 | BX49: 167522 | BY49: 172942 | BZ49: 167104 | CA49: 162149 | CB49: 175557 | CC49: 178569 | CD49: 172701 | CE49: 166686 | CF49: 179470 | CG49: 183803 | CH49: 178882 | CI49: 171857 | CJ49: 185945 | CK49: 188371 | CL49: 185596 | CM49: 180198 | CN49: 191532 | CO49: 197267 | CP49: 189494 | CQ49: 180093 | CR49: 193900 | CS49: 192288 | CT49: 184350 | CU49: 176073 | CV49: 185965 | CW49: 183451 | CX49: 176431 | CY49: 173576 | CZ49: 187866 | DA49: 190027 | DB49: 180958 | DC49: 180307 | DD49: 189544 | DE49: 185466 | DF49: 179219 | DG49: 174171 | DH49: 185125 | DI49: 182847 | DJ49: 176187 | DK49: 171884 | DL49: 184436 | DM49: 182374 | DN49: 175973 | DO49: 173654 | DP49: 187000

Sheet art
A1: Provincia | B1: 44136 | C1: 44166 | D1: 44197 | E1: 44228 | F1: 44256 | G1: 44287 | H1: 44317 | I1: 44348 | J1: 44378 | K1: 44409 | L1: 44440 | M1: 44470 | N1: 44501 | O1: 44531 | P1: 44562 | Q1: 44593 | R1: 44621 | S1: 44652 | T1: 44682 | U1: 44713 | V1: 44743 | W1: 44774 | X1: 44805 | Y1: 44835 | Z1: 44866 | AA1: 44896 | AB1: 44927 | AC1: 44958 | AD1: 44986 | AE1: 45017 | AF1: 45047 | AG1: 45078 | AH1: 45108 | AI1: 45139 | AJ1: 45170 | AK1: 45200 | AL1: 45231 | AM1: 45261 | AN1: 45292 | AO1: 45323 | AP1: 45352 | AQ1: 45383 | AR1: 45413 | AS1: 45444 | AT1: 45474 | AU1: 45505 | AV1: 45536 | AW1: 45566 | AX1: 45597 | AY1: 45627 | AZ1: 45658 | BA1: 45689 | BB1: 45717 | BC1: 45748 | BD1: 45778 | BE1: 45809 | BF1: 45839 | BG1: 45870 | BH1: 45901 | BI1: 45931
A2: Buenos Aires | B2: 0.034 | C2: 0.034 | D2: 0.034 | E2: 0.0335 | F2: 0.033 | G2: 0.032 | H2: 0.033 | I2: 0.033 | J2: 0.033 | K2: 0.033 | L2: 0.033 | M2: 0.032 | N2: 0.032 | O2: 0.032 | P2: 0.032 | Q2: 0.032 | R2: 0.032 | S2: 0.03 | T2: 0.031 | U2: 0.032 | V2: 0.031 | W2: 0.032 | X2: 0.032 | Y2: 0.031 | Z2: 0.031 | AA2: 0.031 | AB2: 0.031 | AC2: 0.031 | AD2: 0.031 | AE2: 0.03 | AF2: 0.031 | AG2: 0.032 | AH2: 0.032 | AI2: 0.033 | AJ2: 0.033 | AK2: 0.032 | AL2: 0.032 | AM2: 0.033 | AN2: 0.032 | AO2: 0.032 | AP2: 0.032 | AQ2: 0.031 | AR2: 0.032 | AS2: 0.033 | AT2: 0.033 | AU2: 0.034 | AV2: 0.034 | AW2: 0.033 | AX2: 0.034 | AY2: 0.034 | AZ2: 0.034 | BA2: 0.034 | BB2: 0.035 | BC2: 0.035 | BD2: 0.036 | BE2: 0.036 | BF2: 0.037 | BG2: 0.038 | BH2: 0.038 | BI2: 0.038
A3: CABA | B3: 0.028 | C3: 0.028 | D3: 0.028 | E3: 0.0275 | F3: 0.027 | G3: 0.026 | H3: 0.027 | I3: 0.027 | J3: 0.027 | K3: 0.027 | L3: 0.027 | M3: 0.027 | N3: 0.027 | O3: 0.027 | P3: 0.027 | Q3: 0.027 | R3: 0.026 | S3: 0.025 | T3: 0.026 | U3: 0.027 | V3: 0.026 | W3: 0.026 | X3: 0.027 | Y3: 0.026 | Z3: 0.026 | AA3: 0.026 | AB3: 0.026 | AC3: 0.026 | AD3: 0.026 | AE3: 0.025 | AF3: 0.026 | AG3: 0.026 | AH3: 0.027 | AI3: 0.026 | AJ3: 0.027 | AK3: 0.027 | AL3: 0.028 | AM3: 0.027 | AN3: 0.027 | AO3: 0.027 | AP3: 0.027 | AQ3: 0.026 | AR3: 0.027 | AS3: 0.028 | AT3: 0.027 | AU3: 0.028 | AV3: 0.028 | AW3: 0.027 | AX3: 0.028 | AY3: 0.028 | AZ3: 0.029 | BA3: 0.028 | BB3: 0.029 | BC3: 0.028 | BD3: 0.029 | BE3: 0.031 | BF3: 0.03 | BG3: 0.031 | BH3: 0.032 | BI3: 0.031
A4: Catamarca | B4: 0.032 | C4: 0.031 | D4: 0.03 | E4: 0.0305 | F4: 0.031 | G4: 0.032 | H4: 0.032 | I4: 0.032 | J4: 0.032 | K4: 0.031 | L4: 0.033 | M4: 0.032 | N4: 0.032 | O4: 0.031 | P4: 0.03 | Q4: 0.032 | R4: 0.031 | S4: 0.031 | T4: 0.032 | U4: 0.032 | V4: 0.031 | W4: 0.032 | X4: 0.031 | Y4: 0.031 | Z4: 0.031 | AA4: 0.031 | AB4: 0.03 | AC4: 0.033 | AD4: 0.032 | AE4: 0.033 | AF4: 0.032 | AG4: 0.033 | AH4: 0.032 | AI4: 0.033 | AJ4: 0.033 | AK4: 0.033 | AL4: 0.033 | AM4: 0.032 | AN4: 0.031 | AO4: 0.035 | AP4: 0.034 | AQ4: 0.033 | AR4: 0.033 | AS4: 0.034 | AT4: 0.034 | AU4: 0.034 | AV4: 0.035 | AW4: 0.035 | AX4: 0.035 | AY4: 0.034 | AZ4: 0.034 | BA4: 0.035 | BB4: 0.034 | BC4: 0.035 | BD4: 0.036 | BE4: 0.037 | BF4: 0.036 | BG4: 0.037 | BH4: 0.039 | BI4: 0.039
A5: Chaco | B5: 0.052 | C5: 0.05 | D5: 0.05 | E5: 0.05 | F5: 0.05 | G5: 0.049 | H5: 0.05 | I5: 0.05 | J5: 0.051 | K5: 0.051 | L5: 0.05 | M5: 0.05 | N5: 0.048 | O5: 0.048 | P5: 0.05 | Q5: 0.05 | R5: 0.05 | S5: 0.049 | T5: 0.05 | U5: 0.049 | V5: 0.051 | W5: 0.052 | X5: 0.05 | Y5: 0.052 | Z5: 0.051 | AA5: 0.05 | AB5: 0.05 | AC5: 0.051 | AD5: 0.051 | AE5: 0.053 | AF5: 0.052 | AG5: 0.052 | AH5: 0.052 | AI5: 0.054 | AJ5: 0.054 | AK5: 0.055 | AL5: 0.055 | AM5: 0.054 | AN5: 0.054 | AO5: 0.053 | AP5: 0.053 | AQ5: 0.054 | AR5: 0.052 | AS5: 0.055 | AT5: 0.054 | AU5: 0.055 | AV5: 0.054 | AW5: 0.052 | AX5: 0.051 | AY5: 0.051 | AZ5: 0.051 | BA5: 0.051 | BB5: 0.053 | BC5: 0.054 | BD5: 0.055 | BE5: 0.055 | BF5: 0.055 | BG5: 0.057 | BH5: 0.056 | BI5: 0.057
A6: Chubut | B6: 0.041 | C6: 0.042 | D6: 0.044 | E6: 0.045 | F6: 0.046 | G6: 0.042 | H6: 0.042 | I6: 0.043 | J6: 0.044 | K6: 0.046 | L6: 0.045 | M6: 0.043 | N6: 0.041 | O6: 0.043 | P6: 0.044 | Q6: 0.044 | R6: 0.042 | S6: 0.042 | T6: 0.041 | U6: 0.042 | V6: 0.042 | W6: 0.043 | X6: 0.044 | Y6: 0.041 | Z6: 0.04 | AA6: 0.042 | AB6: 0.044 | AC6: 0.045 | AD6: 0.043 | AE6: 0.041 | AF6: 0.04 | AG6: 0.04 | AH6: 0.04 | AI6: 0.042 | AJ6: 0.042 | AK6: 0.041 | AL6: 0.039 | AM6: 0.04 | AN6: 0.044 | AO6: 0.044 | AP6: 0.043 | AQ6: 0.041 | AR6: 0.04 | AS6: 0.042 | AT6: 0.044 | AU6: 0.046 | AV6: 0.046 | AW6: 0.043 | AX6: 0.043 | AY6: 0.047 | AZ6: 0.046 | BA6: 0.046 | BB6: 0.047 | BC6: 0.045 | BD6: 0.046 | BE6: 0.047 | BF6: 0.046 | BG6: 0.045 | BH6: 0.053 | BI6: 0.053
A7: Córdoba | B7: 0.037 | C7: 0.036 | D7: 0.035 | E7: 0.0355 | F7: 0.036 | G7: 0.035 | H7: 0.035 | I7: 0.035 | J7: 0.035 | K7: 0.035 | L7: 0.035 | M7: 0.035 | N7: 0.035 | O7: 0.034 | P7: 0.034 | Q7: 0.034 | R7: 0.034 | S7: 0.034 | T7: 0.034 | U7: 0.034 | V7: 0.034 | W7: 0.034 | X7: 0.034 | Y7: 0.035 | Z7: 0.034 | AA7: 0.034 | AB7: 0.034 | AC7: 0.034 | AD7: 0.033 | AE7: 0.035 | AF7: 0.034 | AG7: 0.036 | AH7: 0.036 | AI7: 0.036 | AJ7: 0.037 | AK7: 0.037 | AL7: 0.037 | AM7: 0.037 | AN7: 0.036 | AO7: 0.037 | AP7: 0.036 | AQ7: 0.036 | AR7: 0.038 | AS7: 0.038 | AT7: 0.039 | AU7: 0.039 | AV7: 0.039 | AW7: 0.039 | AX7: 0.039 | AY7: 0.039 | AZ7: 0.039 | BA7: 0.039 | BB7: 0.039 | BC7: 0.04 | BD7: 0.041 | BE7: 0.042 | BF7: 0.042 | BG7: 0.043 | BH7: 0.044 | BI7: 0.044
A8: Corrientes | B8: 0.035 | C8: 0.036 | D8: 0.035 | E8: 0.035 | F8: 0.035 | G8: 0.035 | H8: 0.034 | I8: 0.035 | J8: 0.036 | K8: 0.037 | L8: 0.037 | M8: 0.037 | N8: 0.037 | O8: 0.037 | P8: 0.038 | Q8: 0.038 | R8: 0.038 | S8: 0.035 | T8: 0.037 | U8: 0.039 | V8: 0.039 | W8: 0.039 | X8: 0.04 | Y8: 0.039 | Z8: 0.037 | AA8: 0.038 | AB8: 0.037 | AC8: 0.036 | AD8: 0.037 | AE8: 0.037 | AF8: 0.038 | AG8: 0.039 | AH8: 0.039 | AI8: 0.039 | AJ8: 0.039 | AK8: 0.039 | AL8: 0.038 | AM8: 0.038 | AN8: 0.038 | AO8: 0.039 | AP8: 0.04 | AQ8: 0.04 | AR8: 0.04 | AS8: 0.042 | AT8: 0.042 | AU8: 0.043 | AV8: 0.042 | AW8: 0.043 | AX8: 0.042 | AY8: 0.043 | AZ8: 0.042 | BA8: 0.042 | BB8: 0.043 | BC8: 0.041 | BD8: 0.043 | BE8: 0.045 | BF8: 0.045 | BG8: 0.046 | BH8: 0.046 | BI8: 0.045
A9: Entre Ríos | B9: 0.046 | C9: 0.045 | D9: 0.044 | E9: 0.0435 | F9: 0.043 | G9: 0.044 | H9: 0.043 | I9: 0.044 | J9: 0.045 | K9: 0.045 | L9: 0.045 | M9: 0.044 | N9: 0.043 | O9: 0.043 | P9: 0.043 | Q9: 0.043 | R9: 0.043 | S9: 0.043 | T9: 0.043 | U9: 0.043 | V9: 0.044 | W9: 0.043 | X9: 0.044 | Y9: 0.044 | Z9: 0.042 | AA9: 0.043 | AB9: 0.043 | AC9: 0.043 | AD9: 0.043 | AE9: 0.044 | AF9: 0.043 | AG9: 0.045 | AH9: 0.045 | AI9: 0.045 | AJ9: 0.045 | AK9: 0.045 | AL9: 0.045 | AM9: 0.045 | AN9: 0.045 | AO9: 0.046 | AP9: 0.046 | AQ9: 0.046 | AR9: 0.046 | AS9: 0.046 | AT9: 0.046 | AU9: 0.047 | AV9: 0.047 | AW9: 0.046 | AX9: 0.047 | AY9: 0.046 | AZ9: 0.046 | BA9: 0.046 | BB9: 0.045 | BC9: 0.046 | BD9: 0.046 | BE9: 0.047 | BF9: 0.047 | BG9: 0.048 | BH9: 0.048 | BI9: 0.049
A10: Formosa | B10: 0.034 | C10: 0.032 | D10: 0.029 | E10: 0.0305 | F10: 0.032 | G10: 0.033 | H10: 0.032 | I10: 0.037 | J10: 0.034 | K10: 0.035 | L10: 0.034 | M10: 0.031 | N10: 0.033 | O10: 0.033 | P10: 0.029 | Q10: 0.032 | R10: 0.032 | S10: 0.033 | T10: 0.033 | U10: 0.034 | V10: 0.034 | W10: 0.035 | X10: 0.034 | Y10: 0.036 | Z10: 0.034 | AA10: 0.038 | AB10: 0.033 | AC10: 0.036 | AD10: 0.037 | AE10: 0.037 | AF10: 0.038 | AG10: 0.041 | AH10: 0.037 | AI10: 0.037 | AJ10: 0.037 | AK10: 0.037 | AL10: 0.036 | AM10: 0.035 | AN10: 0.034 | AO10: 0.034 | AP10: 0.036 | AQ10: 0.035 | AR10: 0.035 | AS10: 0.037 | AT10: 0.036 | AU10: 0.033 | AV10: 0.034 | AW10: 0.034 | AX10: 0.033 | AY10: 0.033 | AZ10: 0.033 | BA10: 0.033 | BB10: 0.036 | BC10: 0.038 | BD10: 0.038 | BE10: 0.04 | BF10: 0.039 | BG10: 0.041 | BH10: 0.042 | BI10: 0.042
A11: Jujuy | B11: 0.023 | C11: 0.023 | D11: 0.024 | E11: 0.024 | F11: 0.024 | G11: 0.025 | H11: 0.025 | I11: 0.025 | J11: 0.022 | K11: 0.022 | L11: 0.022 | M11: 0.022 | N11: 0.02 | O11: 0.023 | P11: 0.022 | Q11: 0.024 | R11: 0.025 | S11: 0.025 | T11: 0.024 | U11: 0.024 | V11: 0.022 | W11: 0.023 | X11: 0.023 | Y11: 0.022 | Z11: 0.022 | AA11: 0.023 | AB11: 0.024 | AC11: 0.025 | AD11: 0.026 | AE11: 0.025 | AF11: 0.026 | AG11: 0.026 | AH11: 0.024 | AI11: 0.024 | AJ11: 0.024 | AK11: 0.025 | AL11: 0.023 | AM11: 0.025 | AN11: 0.028 | AO11: 0.028 | AP11: 0.028 | AQ11: 0.028 | AR11: 0.028 | AS11: 0.029 | AT11: 0.027 | AU11: 0.027 | AV11: 0.028 | AW11: 0.026 | AX11: 0.028 | AY11: 0.027 | AZ11: 0.032 | BA11: 0.032 | BB11: 0.033 | BC11: 0.034 | BD11: 0.033 | BE11: 0.034 | BF11: 0.034 | BG11: 0.033 | BH11: 0.034 | BI11: 0.033
A12: La Pampa | B12: 0.05 | C12: 0.05 | D12: 0.05 | E12: 0.0495 | F12: 0.049 | G12: 0.049 | H12: 0.049 | I12: 0.048 | J12: 0.048 | K12: 0.048 | L12: 0.048 | M12: 0.047 | N12: 0.047 | O12: 0.048 | P12: 0.045 | Q12: 0.047 | R12: 0.047 | S12: 0.046 | T12: 0.045 | U12: 0.046 | V12: 0.046 | W12: 0.046 | X12: 0.047 | Y12: 0.047 | Z12: 0.046 | AA12: 0.046 | AB12: 0.046 | AC12: 0.046 | AD12: 0.045 | AE12: 0.046 | AF12: 0.046 | AG12: 0.047 | AH12: 0.047 | AI12: 0.047 | AJ12: 0.047 | AK12: 0.048 | AL12: 0.047 | AM12: 0.048 | AN12: 0.047 | AO12: 0.046 | AP12: 0.046 | AQ12: 0.046 | AR12: 0.046 | AS12: 0.048 | AT12: 0.048 | AU12: 0.047 | AV12: 0.049 | AW12: 0.049 | AX12: 0.049 | AY12: 0.049 | AZ12: 0.048 | BA12: 0.047 | BB12: 0.048 | BC12: 0.048 | BD12: 0.048 | BE12: 0.05 | BF12: 0.05 | BG12: 0.05 | BH12: 0.051 | BI12: 0.052
... A25: Tucumán | B25: 0.03 | C25: 0.029 | D25: 0.028 | E25: 0.028 | F25: 0.028 | G25: 0.029 | H25: 0.028 | I25: 0.028 | J25: 0.028 | K25: 0.028 | L25: 0.029 | M25: 0.029 | N25: 0.029 | O25: 0.028 | P25: 0.027 | Q25: 0.028 | R25: 0.028 | S25: 0.027 | T25: 0.027 | U25: 0.028 | V25: 0.028 | W25: 0.029 | X25: 0.029 | Y25: 0.028 | Z25: 0.027 | AA25: 0.028 | AB25: 0.027 | AC25: 0.026 | AD25: 0.028 | AE25: 0.028 | AF25: 0.028 | AG25: 0.029 | AH25: 0.03 | AI25: 0.03 | AJ25: 0.031 | AK25: 0.03 | AL25: 0.03 | AM25: 0.029 | AN25: 0.029 | AO25: 0.029 | AP25: 0.03 | AQ25: 0.029 | AR25: 0.03 | AS25: 0.03 | AT25: 0.032 | AU25: 0.032 | AV25: 0.032 | AW25: 0.032 | AX25: 0.031 | AY25: 0.032 | AZ25: 0.031 | BA25: 0.029 | BB25: 0.031 | BC25: 0.032 | BD25: 0.031 | BE25: 0.033 | BF25: 0.033 | BG25: 0.035 | BH25: 0.035 | BI25: 0.036

Sheet vabporsector
A1: provincia | B1: variable | C1: 2004 | D1: 2005 | E1: 2006 | F1: 2007 | G1: 2008 | H1: 2009 | I1: 2010 | J1: 2011 | K1: 2012 | L1: 2013 | M1: 2014 | N1: 2015 | O1: 2016 | P1: 2017 | Q1: 2018 | R1: 2019 | S1: 2020 | T1: 2021 | U1: 2022 | V1: 2023
A2: Buenos Aires | B2: Agricultura, ganaderia, caza y silvicultura | C2: =SUM('[2]Buenos Aires'!C7:C8) -> 11743.85 | D2: =SUM('[2]Buenos Aires'!D7:D8) -> 14030.291 | E2: =SUM('[2]Buenos Aires'!E7:E8) -> 13444.128 | F2: =SUM('[2]Buenos Aires'!F7:F8) -> 13798.096 | G2: =SUM('[2]Buenos Aires'!G7:G8) -> 14265.893 | H2: =SUM('[2]Buenos Aires'!H7:H8) -> 9845.2566 | I2: =SUM('[2]Buenos Aires'!I7:I8) -> 15363.857 | J2: =SUM('[2]Buenos Aires'!J7:J8) -> 15732.189 | ... V2: =SUM('[2]Buenos Aires'!V7:V8) -> 11491.681
A3: Buenos Aires | B3: Pesca y servicios conexos | C3: ='[2]Buenos Aires'!C9 -> 458.77334 | D3: ='[2]Buenos Aires'!D9 -> 447.61856 | E3: ='[2]Buenos Aires'!E9 -> 613.18154 | F3: ='[2]Buenos Aires'!F9 -> 570.16729 | G3: ='[2]Buenos Aires'!G9 -> 638.29237 | H3: ='[2]Buenos Aires'!H9 -> 543.8246 | I3: ='[2]Buenos Aires'!I9 -> 568.62792 | J3: ='[2]Buenos Aires'!J9 -> 567.49051 | ... V3: ='[2]Buenos Aires'!V9 -> 710.60121
A4: Buenos Aires | B4: Explotacion de minas y canteras | C4: =SUM('[2]Buenos Aires'!C10:C11) -> 345.12862 | D4: =SUM('[2]Buenos Aires'!D10:D11) -> 408.12596 | E4: =SUM('[2]Buenos Aires'!E10:E11) -> 454.11377 | F4: =SUM('[2]Buenos Aires'!F10:F11) -> 446.90378 | G4: =SUM('[2]Buenos Aires'!G10:G11) -> 431.09043 | H4: =SUM('[2]Buenos Aires'!H10:H11) -> 466.86716 | I4: =SUM('[2]Buenos Aires'!I10:I11) -> 501.56166 | J4: =SUM('[2]Buenos Aires'!J10:J11) -> 474.81193 | ... V4: =SUM('[2]Buenos Aires'!V10:V11) -> 634.27287
A5: Buenos Aires | B5: Industria manufacturera | C5: =SUM('[2]Buenos Aires'!C12:C35) -> 43772.662 | D5: =SUM('[2]Buenos Aires'!D12:D35) -> 47111.497 | E5: =SUM('[2]Buenos Aires'!E12:E35) -> 51234.002 | F5: =SUM('[2]Buenos Aires'!F12:F35) -> 54907.221 | G5: =SUM('[2]Buenos Aires'!G12:G35) -> 57029.616 | H5: =SUM('[2]Buenos Aires'!H12:H35) -> 53104.955 | I5: =SUM('[2]Buenos Aires'!I12:I35) -> 59203.49 | J5: =SUM('[2]Buenos Aires'!J12:J35) -> 63157.457 | ... V5: =SUM('[2]Buenos Aires'!V12:V35) -> 57965.056
A6: Buenos Aires | B6: Electricidad, gas y agua | C6: =SUM('[2]Buenos Aires'!C36:C38) -> 2969.6338 | D6: =SUM('[2]Buenos Aires'!D36:D38) -> 3146.9759 | E6: =SUM('[2]Buenos Aires'!E36:E38) -> 3291.6964 | F6: =SUM('[2]Buenos Aires'!F36:F38) -> 3335.9835 | G6: =SUM('[2]Buenos Aires'!G36:G38) -> 3458.4493 | H6: =SUM('[2]Buenos Aires'!H36:H38) -> 3272.4365 | I6: =SUM('[2]Buenos Aires'!I36:I38) -> 3339.3157 | J6: =SUM('[2]Buenos Aires'!J36:J38) -> 3453.4038 | ... V6: =SUM('[2]Buenos Aires'!V36:V38) -> 4171.8719
A7: Buenos Aires | B7: Construccion | C7: ='[2]Buenos Aires'!C39 -> 4354.1428 | D7: ='[2]Buenos Aires'!D39 -> 4536.5902 | E7: ='[2]Buenos Aires'!E39 -> 5286.9146 | F7: ='[2]Buenos Aires'!F39 -> 5857.0103 | G7: ='[2]Buenos Aires'!G39 -> 6239.0011 | H7: ='[2]Buenos Aires'!H39 -> 5604.9311 | I7: ='[2]Buenos Aires'!I39 -> 6192.1955 | J7: ='[2]Buenos Aires'!J39 -> 6656.3013 | ... V7: ='[2]Buenos Aires'!V39 -> 6654.61
A8: Buenos Aires | B8: Comercio al por mayor y al por menor | C8: ='[2]Buenos Aires'!C40 -> 18983.731 | D8: ='[2]Buenos Aires'!D40 -> 21038.39 | E8: ='[2]Buenos Aires'!E40 -> 23319.094 | F8: ='[2]Buenos Aires'!F40 -> 25489.167 | G8: ='[2]Buenos Aires'!G40 -> 26995.645 | H8: ='[2]Buenos Aires'!H40 -> 24737.254 | I8: ='[2]Buenos Aires'!I40 -> 28354.546 | J8: ='[2]Buenos Aires'!J40 -> 31335.859 | ... V8: ='[2]Buenos Aires'!V40 -> 31061.141
A9: Buenos Aires | B9: Hotelería y restaurantes | C9: =SUM('[2]Buenos Aires'!C41:C42) -> 1557.3925 | D9: =SUM('[2]Buenos Aires'!D41:D42) -> 1828.405 | E9: =SUM('[2]Buenos Aires'!E41:E42) -> 2075.4841 | F9: =SUM('[2]Buenos Aires'!F41:F42) -> 2404.7242 | G9: =SUM('[2]Buenos Aires'!G41:G42) -> 2393.9934 | H9: =SUM('[2]Buenos Aires'!H41:H42) -> 2343.6984 | I9: =SUM('[2]Buenos Aires'!I41:I42) -> 2597.5913 | J9: =SUM('[2]Buenos Aires'!J41:J42) -> 2763.5936 | ... V9: =SUM('[2]Buenos Aires'!V41:V42) -> 2716.5941
A10: Buenos Aires | B10: Transporte, de almacenamiento y de comunicaciones | C10: =SUM('[2]Buenos Aires'!C43:C44) -> 9772.6463 | D10: =SUM('[2]Buenos Aires'!D43:D44) -> 11000.289 | E10: =SUM('[2]Buenos Aires'!E43:E44) -> 12193.518 | F10: =SUM('[2]Buenos Aires'!F43:F44) -> 13813.354 | G10: =SUM('[2]Buenos Aires'!G43:G44) -> 14754.224 | H10: =SUM('[2]Buenos Aires'!H43:H44) -> 14709.406 | I10: =SUM('[2]Buenos Aires'!I43:I44) -> 16486.444 | J10: =SUM('[2]Buenos Aires'!J43:J44) -> 17984.086 | ... V10: =SUM('[2]Buenos Aires'!V43:V44) -> 20161.892
A11: Buenos Aires | B11: Intermediacion financiera y otros servicios financieros | C11: =SUM('[2]Buenos Aires'!C45:C47) -> 2694.9939 | D11: =SUM('[2]Buenos Aires'!D45:D47) -> 2980.2572 | E11: =SUM('[2]Buenos Aires'!E45:E47) -> 3325.0225 | F11: =SUM('[2]Buenos Aires'!F45:F47) -> 3694.438 | G11: =SUM('[2]Buenos Aires'!G45:G47) -> 3884.5124 | H11: =SUM('[2]Buenos Aires'!H45:H47) -> 3809.445 | I11: =SUM('[2]Buenos Aires'!I45:I47) -> 3914.4534 | J11: =SUM('[2]Buenos Aires'!J45:J47) -> 4394.36 | ... V11: =SUM('[2]Buenos Aires'!V45:V47) -> 4226.7929
A12: Buenos Aires | B12: Servicios inmobiliarios, empresariales y de alquiler | C12: =SUM('[2]Buenos Aires'!C48:C49) -> 16241.108 | D12: =SUM('[2]Buenos Aires'!D48:D49) -> 16867.364 | E12: =SUM('[2]Buenos Aires'!E48:E49) -> 17738.488 | F12: =SUM('[2]Buenos Aires'!F48:F49) -> 18602.107 | G12: =SUM('[2]Buenos Aires'!G48:G49) -> 19380.704 | H12: =SUM('[2]Buenos Aires'!H48:H49) -> 19045.123 | I12: =SUM('[2]Buenos Aires'!I48:I49) -> 19859.083 | J12: =SUM('[2]Buenos Aires'!J48:J49) -> 20549.258 | ... V12: =SUM('[2]Buenos Aires'!V48:V49) -> 23415.058
A13: Buenos Aires | B13: Administración pública | C13: ='[2]Buenos Aires'!C50 -> 5581.8623 | D13: ='[2]Buenos Aires'!D50 -> 6084.1056 | E13: ='[2]Buenos Aires'!E50 -> 6322.4792 | F13: ='[2]Buenos Aires'!F50 -> 6680.7795 | G13: ='[2]Buenos Aires'!G50 -> 7083.7311 | H13: ='[2]Buenos Aires'!H50 -> 7288.991 | I13: ='[2]Buenos Aires'!I50 -> 7425.4993 | J13: ='[2]Buenos Aires'!J50 -> 7524.7032 | ... V13: ='[2]Buenos Aires'!V50 -> 8896.8997
A14: Buenos Aires | B14: Enseñanza | C14: =SUM('[2]Buenos Aires'!C51:C52) -> 5434.9552 | D14: =SUM('[2]Buenos Aires'!D51:D52) -> 6026.8702 | E14: =SUM('[2]Buenos Aires'!E51:E52) -> 6164.3574 | F14: =SUM('[2]Buenos Aires'!F51:F52) -> 6352.4971 | G14: =SUM('[2]Buenos Aires'!G51:G52) -> 6771.974 | H14: =SUM('[2]Buenos Aires'!H51:H52) -> 7107.1233 | I14: =SUM('[2]Buenos Aires'!I51:I52) -> 7143.3392 | J14: =SUM('[2]Buenos Aires'!J51:J52) -> 7372.4172 | ... V14: =SUM('[2]Buenos Aires'!V51:V52) -> 9392.4606
A15: Buenos Aires | B15: Servicios sociales y de salud | C15: =SUM('[2]Buenos Aires'!C53:C54) -> 3282.9242 | D15: =SUM('[2]Buenos Aires'!D53:D54) -> 3564.0994 | E15: =SUM('[2]Buenos Aires'!E53:E54) -> 3495.1899 | F15: =SUM('[2]Buenos Aires'!F53:F54) -> 3714.5502 | G15: =SUM('[2]Buenos Aires'!G53:G54) -> 3996.4792 | H15: =SUM('[2]Buenos Aires'!H53:H54) -> 4409.2371 | I15: =SUM('[2]Buenos Aires'!I53:I54) -> 4515.4994 | J15: =SUM('[2]Buenos Aires'!J53:J54) -> 4621.433 | ... V15: =SUM('[2]Buenos Aires'!V53:V54) -> 5321.3113
A16: Buenos Aires | B16: Servicios comunitarios, sociales y personales n.c.p. | C16: =SUM('[2]Buenos Aires'!C55:C58) -> 4671.9832 | D16: =SUM('[2]Buenos Aires'!D55:D58) -> 5168.1225 | E16: =SUM('[2]Buenos Aires'!E55:E58) -> 5710.1338 | F16: =SUM('[2]Buenos Aires'!F55:F58) -> 6097.355 | G16: =SUM('[2]Buenos Aires'!G55:G58) -> 6337.0255 | H16: =SUM('[2]Buenos Aires'!H55:H58) -> 6389.2284 | I16: =SUM('[2]Buenos Aires'!I55:I58) -> 6730.9185 | J16: =SUM('[2]Buenos Aires'!J55:J58) -> 7009.5202 | ... V16: =SUM('[2]Buenos Aires'!V55:V58) -> 6255.9328
A17: CABA | B17: Agricultura, ganaderia, caza y silvicultura | C17: =SUM([2]CABA!C7:C8) -> 176.38724 | D17: =SUM([2]CABA!D7:D8) -> 188.63128 | E17: =SUM([2]CABA!E7:E8) -> 175.21403 | F17: =SUM([2]CABA!F7:F8) -> 198.39586 | G17: =SUM([2]CABA!G7:G8) -> 208.67355 | H17: =SUM([2]CABA!H7:H8) -> 137.78648 | I17: =SUM([2]CABA!I7:I8) -> 220.09954 | J17: =SUM([2]CABA!J7:J8) -> 205.28285 | ... V17: =SUM([2]CABA!V7:V8) -> 148.69116
